Workbook

Sheet 综合成绩
A1: 综合成绩
A2: 课程：移动应用开发 班级：计科22选49 任课教师：刘东良 导出时间：2026-01-21 01:17:52
A3: 序号 | B3: 学生姓名 | C3: 学号/工号 | D3: 院系 | E3: 专业 | F3: 班级 | G3: 章节任务点(40%) | H3: 章节测验(20%) | I3: 作业(25%) | J3: 考试(15%) | K3: 综合成绩
A4: 1 | B4: 张梦杰 | C4: 2020211034 | D4: 计算机与信息工程学院（大学计算机教学部） | E4: 计算机科学与技术 | F4: 计科222 | G4: 40 | H4: 0 | I4: 18.37 | J4: 5.25 | K4: 63.62
A5: 2 | B5: 童其凡 | C5: 2020213700 | D5: 计算机与信息工程学院（大学计算机教学部） | E5: 计算机科学与技术 | F5: 计科222 | G5: 40 | H5: 0 | I5: 20.96 | J5: 4.5 | K5: 65.46
A6: 3 | B6: 曹安晨 | C6: 2022210331 | D6: 计算机与信息工程学院（大学计算机教学部） | E6: 计算机科学与技术 | F6: 计科221 | G6: 40 | H6: 0 | I6: 22.12 | J6: 4.5 | K6: 66.62
A7: 4 | B7: 陈晨 | C7: 2022210332 | D7: 计算机与信息工程学院（大学计算机教学部） | E7: 计算机科学与技术 | F7: 计科221 | G7: 40 | H7: 0 | I7: 23.08 | J7: 6 | K7: 69.08
A8: 5 | B8: 陈创东 | C8: 2022210333 | D8: 计算机与信息工程学院（大学计算机教学部） | E8: 计算机科学与技术 | F8: 计科221 | G8: 40 | H8: 0 | I8: 21.3 | J8: 5.25 | K8: 66.55
A9: 6 | B9: 程纪阳 | C9: 2022210334 | D9: 计算机与信息工程学院（大学计算机教学部） | E9: 计算机科学与技术 | F9: 计科221 | G9: 40 | H9: 0 | I9: 22.69 | J9: 6 | K9: 68.69
A10: 7 | B10: 程梦圆 | C10: 2022210335 | D10: 计算机与信息工程学院（大学计算机教学部） | E10: 计算机科学与技术 | F10: 计科221 | G10: 40 | H10: 0 | I10: 20.67 | J10: 5.25 | K10: 65.92
A11: 8 | B11: 邓慧茹 | C11: 2022210337 | D11: 计算机与信息工程学院（大学计算机教学部） | E11: 计算机科学与技术 | F11: 计科221 | G11: 40 | H11: 0 | I11: 21.59 | J11: 5.92 | K11: 67.51
A12: 9 | B12: 丁玉耀 | C12: 2022210338 | D12: 计算机与信息工程学院（大学计算机教学部） | E12: 计算机科学与技术 | F12: 计科221 | G12: 40 | H12: 0 | I12: 1.54 | J12: 0 | K12: 41.54
A13: 10 | B13: 范鑫蕊 | C13: 2022210339 | D13: 计算机与信息工程学院（大学计算机教学部） | E13: 计算机科学与技术 | F13: 计科221 | G13: 40 | H13: 0 | I13: 21.63 | J13: 6 | K13: 67.63
A14: 11 | B14: 高恩鹏 | C14: 2022210342 | D14: 计算机与信息工程学院（大学计算机教学部） | E14: 计算机科学与技术 | F14: 计科221 | G14: 40 | H14: 0 | I14: 21.97 | J14: 5.25 | K14: 67.22
A15: 12 | B15: 关雪艳 | C15: 2022210343 | D15: 计算机与信息工程学院（大学计算机教学部） | E15: 计算机科学与技术 | F15: 计科221 | G15: 40 | H15: 0 | I15: 22.74 | J15: 6.75 | K15: 69.49
... A53: 50 | B53: 宗梦晴 | C53: 2022210430 | D53: 计算机与信息工程学院（大学计算机教学部） | E53: 计算机科学与技术 | F53: 计科222 | G53: 40 | H53: 0 | I53: 21.01 | J53: 6 | K53: 67.01

Sheet 综合成绩（各权重项百分制得分）
A1: 综合成绩（各权重项百分制得分）
A2: 课程：移动应用开发 班级：计科22选49 任课教师：刘东良 导出时间：2026-01-21 01:17:52
A3: 序号 | B3: 学生姓名 | C3: 学号/工号 | D3: 院系 | E3: 专业 | F3: 班级 | G3: 章节任务点(100%) | H3: 章节测验(100%) | I3: 作业(100%) | J3: 考试(100%) | K3: 综合成绩
A4: 1 | B4: 张梦杰 | C4: 2020211034 | D4: 计算机与信息工程学院（大学计算机教学部） | E4: 计算机科学与技术 | F4: 计科222 | G4: 100 | H4: 0 | I4: 73.46 | J4: 35 | K4: 63.62
A5: 2 | B5: 童其凡 | C5: 2020213700 | D5: 计算机与信息工程学院（大学计算机教学部） | E5: 计算机科学与技术 | F5: 计科222 | G5: 100 | H5: 0 | I5: 83.85 | J5: 30 | K5: 65.46
A6: 3 | B6: 曹安晨 | C6: 2022210331 | D6: 计算机与信息工程学院（大学计算机教学部） | E6: 计算机科学与技术 | F6: 计科221 | G6: 100 | H6: 0 | I6: 88.46 | J6: 30 | K6: 66.62
A7: 4 | B7: 陈晨 | C7: 2022210332 | D7: 计算机与信息工程学院（大学计算机教学部） | E7: 计算机科学与技术 | F7: 计科221 | G7: 100 | H7: 0 | I7: 92.31 | J7: 40 | K7: 69.08
A8: 5 | B8: 陈创东 | C8: 2022210333 | D8: 计算机与信息工程学院（大学计算机教学部） | E8: 计算机科学与技术 | F8: 计科221 | G8: 100 | H8: 0 | I8: 85.19 | J8: 35 | K8: 66.55
A9: 6 | B9: 程纪阳 | C9: 2022210334 | D9: 计算机与信息工程学院（大学计算机教学部） | E9: 计算机科学与技术 | F9: 计科221 | G9: 100 | H9: 0 | I9: 90.77 | J9: 40 | K9: 68.69
A10: 7 | B10: 程梦圆 | C10: 2022210335 | D10: 计算机与信息工程学院（大学计算机教学部） | E10: 计算机科学与技术 | F10: 计科221 | G10: 100 | H10: 0 | I10: 82.69 | J10: 35 | K10: 65.92
A11: 8 | B11: 邓慧茹 | C11: 2022210337 | D11: 计算机与信息工程学院（大学计算机教学部） | E11: 计算机科学与技术 | F11: 计科221 | G11: 100 | H11: 0 | I11: 86.35 | J11: 39.5 | K11: 67.51
A12: 9 | B12: 丁玉耀 | C12: 2022210338 | D12: 计算机与信息工程学院（大学计算机教学部） | E12: 计算机科学与技术 | F12: 计科221 | G12: 100 | H12: 0 | I12: 6.15 | J12: 0 | K12: 41.54
A13: 10 | B13: 范鑫蕊 | C13: 2022210339 | D13: 计算机与信息工程学院（大学计算机教学部） | E13: 计算机科学与技术 | F13: 计科221 | G13: 100 | H13: 0 | I13: 86.54 | J13: 40 | K13: 67.63
A14: 11 | B14: 高恩鹏 | C14: 2022210342 | D14: 计算机与信息工程学院（大学计算机教学部） | E14: 计算机科学与技术 | F14: 计科221 | G14: 100 | H14: 0 | I14: 87.88 | J14: 35 | K14: 67.22
A15: 12 | B15: 关雪艳 | C15: 2022210343 | D15: 计算机与信息工程学院（大学计算机教学部） | E15: 计算机科学与技术 | F15: 计科221 | G15: 100 | H15: 0 | I15: 90.96 | J15: 45 | K15: 69.49
... A53: 50 | B53: 宗梦晴 | C53: 2022210430 | D53: 计算机与信息工程学院（大学计算机教学部） | E53: 计算机科学与技术 | F53: 计科222 | G53: 100 | H53: 0 | I53: 84.04 | J53: 40 | K53: 67.01

Sheet 学生学习进度详情
A1: 学生学习进度详情
A2: 课程：移动应用开发 班级：计科22选49 任课教师：刘东良 导出时间：2026-01-21 01:17:52
A3: UID | B3: 学生姓名 | C3: 学号/工号 | D3: 院系 | E3: 专业 | F3: 班级 | G3: 入学年份 | H3: 任务完成数 | I3: 任务点完成百分比 | J3: 课程视频进度 | K3: 任务点章节测验进度 | L3: 视频观看时长 | M3: 讨论数 | N3: 章节学习次数 | O3: 学习情况
A4: 152189652 | B4: 张梦杰 | C4: 2020211034 | D4: 计算机与信息工程学院（大学计算机教学部） | E4: 计算机科学与技术 | F4: 计科222 | G4: 2022 | H4: 37/37 | I4: 1 | J4: 16/16 | K4: 0/0 | L4: 88.8分钟 | M4: 0 | N4: 71 | O4: 已学习
A5: 152193210 | B5: 童其凡 | C5: 2020213700 | D5: 计算机与信息工程学院（大学计算机教学部） | E5: 计算机科学与技术 | F5: 计科222 | G5: 2022 | H5: 37/37 | I5: 1 | J5: 16/16 | K5: 0/0 | L5: 101.1分钟 | M5: 0 | N5: 96 | O5: 已学习
A6: 244269082 | B6: 曹安晨 | C6: 2022210331 | D6: 计算机与信息工程学院（大学计算机教学部） | E6: 计算机科学与技术 | F6: 计科221 | G6: 2022 | H6: 37/37 | I6: 1 | J6: 16/16 | K6: 0/0 | L6: 71.7分钟 | M6: 0 | N6: 75 | O6: 已学习
A7: 237944436 | B7: 陈晨 | C7: 2022210332 | D7: 计算机与信息工程学院（大学计算机教学部） | E7: 计算机科学与技术 | F7: 计科221 | G7: 2022 | H7: 37/37 | I7: 1 | J7: 16/16 | K7: 0/0 | L7: 82.2分钟 | M7: 0 | N7: 267 | O7: 已学习
A8: 242926355 | B8: 陈创东 | C8: 2022210333 | D8: 计算机与信息工程学院（大学计算机教学部） | E8: 计算机科学与技术 | F8: 计科221 | G8: 2022 | H8: 37/37 | I8: 1 | J8: 16/16 | K8: 0/0 | L8: 103.1分钟 | M8: 0 | N8: 72 | O8: 已学习
A9: 242927109 | B9: 程纪阳 | C9: 2022210334 | D9: 计算机与信息工程学院（大学计算机教学部） | E9: 计算机科学与技术 | F9: 计科221 | G9: 2022 | H9: 37/37 | I9: 1 | J9: 16/16 | K9: 0/0 | L9: 72.4分钟 | M9: 0 | N9: 118 | O9: 已学习
A10: 244269085 | B10: 程梦圆 | C10: 2022210335 | D10: 计算机与信息工程学院（大学计算机教学部） | E10: 计算机科学与技术 | F10: 计科221 | G10: 2022 | H10: 37/37 | I10: 1 | J10: 16/16 | K10: 0/0 | L10: 62.6分钟 | M10: 0 | N10: 94 | O10: 已学习
A11: 242896753 | B11: 邓慧茹 | C11: 2022210337 | D11: 计算机与信息工程学院（大学计算机教学部） | E11: 计算机科学与技术 | F11: 计科221 | G11: 2022 | H11: 36/37 | I11: 0.973 | J11: 16/16 | K11: 0/0 | L11: 106.0分钟 | M11: 0 | N11: 107 | O11: 已学习
A12: 244269092 | B12: 丁玉耀 | C12: 2022210338 | D12: 计算机与信息工程学院（大学计算机教学部） | E12: 计算机科学与技术 | F12: 计科221 | G12: 2022 | H12: 37/37 | I12: 1 | J12: 16/16 | K12: 0/0 | L12: 49.8分钟 | M12: 0 | N12: 22 | O12: 已学习
A13: 242938888 | B13: 范鑫蕊 | C13: 2022210339 | D13: 计算机与信息工程学院（大学计算机教学部） | E13: 计算机科学与技术 | F13: 计科221 | G13: 2022 | H13: 37/37 | I13: 1 | J13: 16/16 | K13: 0/0 | L13: 96.2分钟 | M13: 0 | N13: 135 | O13: 已学习
A14: 242926726 | B14: 高恩鹏 | C14: 2022210342 | D14: 计算机与信息工程学院（大学计算机教学部） | E14: 计算机科学与技术 | F14: 计科221 | G14: 2022 | H14: 37/37 | I14: 1 | J14: 16/16 | K14: 0/0 | L14: 100.5分钟 | M14: 0 | N14: 125 | O14: 已学习
A15: 244269102 | B15: 关雪艳 | C15: 2022210343 | D15: 计算机与信息工程学院（大学计算机教学部） | E15: 计算机科学与技术 | F15: 计科221 | G15: 2022 | H15: 37/37 | I15: 1 | J15: 16/16 | K15: 0/0 | L15: 52.3分钟 | M15: 0 | N15: 98 | O15: 已学习
... A53: 243065959 | B53: 宗梦晴 | C53: 2022210430 | D53: 计算机与信息工程学院（大学计算机教学部） | E53: 计算机科学与技术 | F53: 计科222 | G53: 2022 | H53: 37/37 | I53: 1 | J53: 16/16 | K53: 0/0 | L53: 50.4分钟 | M53: 0 | N53: 100 | O53: 已学习

Sheet 章节学习次数
A1: 章节学习次数
A2: 课程：移动应用开发 班级：计科22选49 任课教师：刘东良 导出时间：2026-01-21 01:17:52
A3: 日期 | B3: 学习页面访问次数 | C3: 时段（00-04） | D3: 时段（04-08） | E3: 时段（08-12） | F3: 时段（12-16） | G3: 时段（16-20） | H3: 时段（20-24）
A4: 2025-9-4 | B4: 375 | C4: 0 | D4: 13 | E4: 339 | F4: 3 | G4: 4 | H4: 16
A5: 2025-9-5 | B5: 49 | C5: 7 | D5: 0 | E5: 12 | F5: 28 | G5: 2 | H5: 0
A6: 2025-9-6 | B6: 10 | C6: 0 | D6: 0 | E6: 4 | F6: 2 | G6: 4 | H6: 0
A7: 2025-9-7 | B7: 47 | C7: 0 | D7: 0 | E7: 9 | F7: 5 | G7: 3 | H7: 30
A8: 2025-9-8 | B8: 94 | C8: 0 | D8: 0 | E8: 93 | F8: 0 | G8: 1 | H8: 0
A9: 2025-9-9 | B9: 30 | C9: 0 | D9: 0 | E9: 2 | F9: 0 | G9: 6 | H9: 22
A10: 2025-9-10 | B10: 395 | C10: 0 | D10: 0 | E10: 378 | F10: 10 | G10: 3 | H10: 4
A11: 2025-9-11 | B11: 192 | C11: 3 | D11: 32 | E11: 143 | F11: 3 | G11: 1 | H11: 10
A12: 2025-9-12 | B12: 66 | C12: 0 | D12: 0 | E12: 1 | F12: 1 | G12: 10 | H12: 54
A13: 2025-9-13 | B13: 196 | C13: 4 | D13: 2 | E13: 13 | F13: 43 | G13: 60 | H13: 74
A14: 2025-9-14 | B14: 144 | C14: 1 | D14: 0 | E14: 9 | F14: 63 | G14: 56 | H14: 15
A15: 2025-9-15 | B15: 67 | C15: 0 | D15: 0 | E15: 63 | F15: 1 | G15: 0 | H15: 3
... A126: 2026-1-17 | B126: 1 | C126: 0 | D126: 0 | E126: 0 | F126: 1 | G126: 0 | H126: 0

Sheet 任务点完成详情
A1: 任务点完成详情
A2: 课程：移动应用开发 班级：计科22选49 任课教师：刘东良 导出时间：2026-01-21 01:17:52
A3: 学生姓名 | B3: 学号/工号 | C3: 院系 | D3: 专业 | E3: 班级 | F3: 教学大纲 | H3: 教学进度表 | J3: 学习指导手册 | L3: 教学案例 | N3: 课程考核 | P3: 第一章 移动应用开发技术体系1 | T3: 第一章 移动应用开发技术体系2 | X3: 第二章 原生开发基础1 | AB3: 第二章 原生开发基础2 | AF3: 第三章 混合开发技术1 | AJ3: 第三章 混合开发技术2 | AN3: 第三章 混合开发技术3 | AR3: 第四章 小程序开发1 | AV3: 第四章 小程序开发2 | AZ3: 第五章 华为多端应用开发1 | BD3: 第五章 华为多端应用开发2 | BH3: 第五章 华为多端应用开发3 | BL3: 第六章 综合开发实践1 | BP3: 第六章 综合开发实践2 | BT3: 第六章 综合开发实践3 | BX3: 课程教学评价问卷 | BZ3: 课程达成度评价问卷
F4: 计科+6+《移动应用开发》+刘东良.docx | H4: 计科22+《移动应用开发》教学进度表+刘东良.doc | J4: 移动应用开发学生学习指导手册.docx | L4: 1c029654795cf1e1be5da6ed5ee4cfac.mp4 | N4: 移动应用开发综合考核方案.docx | P4: 第一章 移动应用开发技术体系1.pptx | R4: 第一章 移动应用开发技术体系1.mp4 | T4: 第一章 移动应用开发技术体系2.pptx | V4: 第一章 移动应用开发技术体系2.mp4 | X4: 第二章 原生开发基础1.pptx | Z4: 第二章 原生开发基础1.mp4 | AB4: 第二章 原生开发基础2.pptx | AD4: 第二章 原生开发基础2.mp4 | AF4: 第三章 混合开发技术1.pptx | AH4: 第三章 混合开发技术1.mp4 | AJ4: 第三章 混合开发技术2.pptx | AL4: 第三章 混合开发技术2.mp4 | AN4: 第三章 混合开发技术3.pptx | AP4: 第三章 混合开发技术3.mp4 | AR4: 第四章 小程序开发1.pptx | AT4: 第四章 小程序开发1.mp4 | AV4: 第四章 小程序开发2.pptx | AX4: 第四章 小程序开发2.mp4 | AZ4: 第五章 华为多端应用开发1.pptx | BB4: 第五章 华为多端应用开发1.mp4 | BD4: 第五章 华为多端应用开发2.pptx | BF4: 第五章 华为多端应用开发2(1).mp4 | BH4: 第五章 华为多端应用开发3.pptx | BJ4: 第五章 华为多端应用开发3.mp4 | BL4: 第六章 综合开发实践1.pptx | BN4: 第六章 综合开发实践1.mp4 | BP4: 第六章 综合开发实践2.pptx | BR4: 第六章 综合开发实践2.mp4 | BT4: 第六章 综合开发实践3.pptx | BV4: 第六章 综合开发实践3.mp4 | BX4: 课程学后调查 | BZ4: 课程目标支撑毕业要求达成度调查问卷
F5: 状态 | G5: 完成时间 | H5: 状态 | I5: 完成时间 | J5: 状态 | K5: 完成时间 | L5: 状态 | M5: 完成时间 | N5: 状态 | O5: 完成时间 | P5: 状态 | Q5: 完成时间 | R5: 状态 | S5: 完成时间 | T5: 状态 | U5: 完成时间 | V5: 状态 | W5: 完成时间 | X5: 状态 | Y5: 完成时间 | Z5: 状态 | AA5: 完成时间 | AB5: 状态 | AC5: 完成时间 | AD5: 状态 | AE5: 完成时间 | AF5: 状态 | AG5: 完成时间 | AH5: 状态 | AI5: 完成时间 | AJ5: 状态 | AK5: 完成时间 | AL5: 状态 | AM5: 完成时间 | AN5: 状态 | AO5: 完成时间 | AP5: 状态 | AQ5: 完成时间 | AR5: 状态 | AS5: 完成时间 | AT5: 状态 | AU5: 完成时间 | AV5: 状态 | AW5: 完成时间 | AX5: 状态 | AY5: 完成时间 | AZ5: 状态 | BA5: 完成时间 | BB5: 状态 | BC5: 完成时间 | BD5: 状态 | BE5: 完成时间 | BF5: 状态 | BG5: 完成时间 | BH5: 状态 | BI5: 完成时间 | BJ5: 状态 | BK5: 完成时间 | BL5: 状态 | BM5: 完成时间 | BN5: 状态 | BO5: 完成时间 | BP5: 状态 | BQ5: 完成时间 | BR5: 状态 | BS5: 完成时间 | BT5: 状态 | BU5: 完成时间 | BV5: 状态 | BW5: 完成时间 | BX5: 状态 | BY5: 完成时间 | BZ5: 状态 | CA5: 完成时间
A6: 张梦杰 | B6: 2020211034 | C6: 计算机与信息工程学院（大学计算机教学部） | D6: 计算机科学与技术 | E6: 计科222 | F6: 已完成 | G6: 2025-09-12 21:37 | H6: 已完成 | I6: 2025-09-12 21:38 | J6: 已完成 | K6: 2025-09-12 21:38 | L6: 已完成 | M6: 2025-09-12 21:50 | N6: 已完成 | O6: 2025-09-12 21:50 | P6: 已完成 | Q6: 2025-09-12 23:19 | R6: 已完成 | S6: 2025-09-12 23:25 | T6: 已完成 | U6: 2025-09-12 23:26 | V6: 已完成 | W6: 2025-09-12 23:31 | X6: 已完成 | Y6: 2025-09-27 17:20 | Z6: 已完成 | AA6: 2025-09-27 17:30 | AB6: 已完成 | AC6: 2025-09-27 17:42 | AD6: 已完成 | AE6: 2025-09-27 17:47 | AF6: 已完成 | AG6: 2025-09-27 17:52 | AH6: 已完成 | AI6: 2025-09-27 17:58 | AJ6: 已完成 | AK6: 2025-09-27 18:00 | AL6: 已完成 | AM6: 2025-09-27 18:05 | AN6: 已完成 | AO6: 2025-09-27 18:06 | AP6: 已完成 | AQ6: 2025-09-27 18:10 | AR6: 已完成 | AS6: 2025-09-27 18:13 | AT6: 已完成 | AU6: 2025-09-27 18:19 | AV6: 已完成 | AW6: 2025-10-25 20:39 | AX6: 已完成 | AY6: 2025-10-25 20:44 | AZ6: 已完成 | BA6: 2025-10-25 20:45 | BB6: 已完成 | BC6: 2025-10-25 20:51 | BD6: 已完成 | BE6: 2025-10-25 21:30 | BF6: 已完成 | BG6: 2025-10-25 21:35 | BH6: 已完成 | BI6: 2025-10-25 21:48 | BJ6: 已完成 | BK6: 2025-10-25 21:51 | BL6: 已完成 | BM6: 2026-01-01 23:40 | BN6: 已完成 | BO6: 2026-01-01 23:44 | BP6: 已完成 | BQ6: 2026-01-01 23:45 | BR6: 已完成 | BS6: 2026-01-01 23:50 | BT6: 已完成 | BU6: 2026-01-01 23:51 | BV6: 已完成 | BW6: 2026-01-01 23:56 | BX6: 已完成 | BY6: 2026-01-01 23:57 | BZ6: 已完成 | CA6: 2026-01-15 18:56
A7: 童其凡 | B7: 2020213700 | C7: 计算机与信息工程学院（大学计算机教学部） | D7: 计算机科学与技术 | E7: 计科222 | F7: 已完成 | G7: 2025-09-04 08:08 | H7: 已完成 | I7: 2025-09-04 08:09 | J7: 已完成 | K7: 2025-09-04 08:09 | L7: 已完成 | M7: 2025-09-07 20:50 | N7: 已完成 | O7: 2025-09-04 08:09 | P7: 已完成 | Q7: 2025-09-09 09:08 | R7: 已完成 | S7: 2025-09-07 20:58 | T7: 已完成 | U7: 2025-09-09 09:08 | V7: 已完成 | W7: 2025-09-09 09:14 | X7: 已完成 | Y7: 2025-09-13 16:36 | Z7: 已完成 | AA7: 2025-09-13 16:46 | AB7: 已完成 | AC7: 2025-09-18 07:57 | AD7: 已完成 | AE7: 2025-09-18 08:02 | AF7: 已完成 | AG7: 2025-09-18 08:05 | AH7: 已完成 | AI7: 2025-09-18 08:11 | AJ7: 已完成 | AK7: 2025-09-18 08:14 | AL7: 已完成 | AM7: 2025-09-18 08:20 | AN7: 已完成 | AO7: 2025-09-18 08:24 | AP7: 已完成 | AQ7: 2025-09-18 08:57 | AR7: 已完成 | AS7: 2025-09-28 10:08 | AT7: 已完成 | AU7: 2025-09-28 10:12 | AV7: 已完成 | AW7: 2025-09-28 10:18 | AX7: 已完成 | AY7: 2025-09-28 10:23 | AZ7: 已完成 | BA7: 2025-09-28 10:25 | BB7: 已完成 | BC7: 2025-09-28 10:30 | BD7: 已完成 | BE7: 2025-10-09 08:20 | BF7: 已完成 | BG7: 2025-10-23 08:08 | BH7: 已完成 | BI7: 2025-10-09 08:28 | BJ7: 已完成 | BK7: 2025-10-09 08:32 | BL7: 已完成 | BM7: 2025-10-23 08:09 | BN7: 已完成 | BO7: 2025-10-23 08:13 | BP7: 已完成 | BQ7: 2025-10-23 08:15 | BR7: 已完成 | BS7: 2025-10-23 08:19 | BT7: 已完成 | BU7: 2025-10-23 08:21 | BV7: 已完成 | BW7: 2025-10-23 08:26 | BX7: 已完成 | BY7: 2026-01-09 19:16 | BZ7: 已完成 | CA7: 2026-01-15 17:37
A8: 曹安晨 | B8: 2022210331 | C8: 计算机与信息工程学院（大学计算机教学部） | D8: 计算机科学与技术 | E8: 计科221 | F8: 已完成 | G8: 2025-09-04 08:08 | H8: 已完成 | I8: 2025-09-04 08:08 | J8: 已完成 | K8: 2025-09-04 08:12 | L8: 已完成 | M8: 2025-09-18 08:49 | N8: 已完成 | O8: 2025-09-04 08:13 | P8: 已完成 | Q8: 2025-09-04 08:08 | R8: 已完成 | S8: 2025-09-18 08:54 | T8: 已完成 | U8: 2025-09-18 08:54 | V8: 已完成 | W8: 2025-09-18 08:58 | X8: 已完成 | Y8: 2025-09-22 10:04 | Z8: 已完成 | AA8: 2025-09-22 10:15 | AB8: 已完成 | AC8: 2025-09-22 10:22 | AD8: 已完成 | AE8: 2025-09-22 10:26 | AF8: 已完成 | AG8: 2025-09-22 10:29 | AH8: 已完成 | AI8: 2025-09-22 10:35 | AJ8: 已完成 | AK8: 2025-09-22 10:38 | AL8: 已完成 | AM8: 2025-09-22 10:44 | AN8: 已完成 | AO8: 2025-10-04 19:04 | AP8: 已完成 | AQ8: 2025-10-04 19:09 | AR8: 已完成 | AS8: 2025-10-04 19:58 | AT8: 已完成 | AU8: 2025-10-04 20:04 | AV8: 已完成 | AW8: 2025-10-04 20:15 | AX8: 已完成 | AY8: 2025-10-04 20:21 | AZ8: 已完成 | BA8: 2025-10-04 20:27 | BB8: 已完成 | BC8: 2025-10-04 20:30 | BD8: 已完成 | BE8: 2025-10-04 20:35 | BF8: 已完成 | BG8: 2025-10-23 08:08 | BH8: 已完成 | BI8: 2025-10-04 20:55 | BJ8: 已完成 | BK8: 2025-10-04 20:57 | BL8: 已完成 | BM8: 2025-10-04 21:14 | BN8: 已完成 | BO8: 2025-10-04 21:16 | BP8: 已完成 | BQ8: 2025-10-04 21:17 | BR8: 已完成 | BS8: 2025-10-04 21:19 | BT8: 已完成 | BU8: 2025-10-04 21:20 | BV8: 已完成 | BW8: 2025-10-04 21:22 | BX8: 已完成 | BY8: 2026-01-09 19:16 | BZ8: 已完成 | CA8: 2026-01-15 17:33
A9: 陈晨 | B9: 2022210332 | C9: 计算机与信息工程学院（大学计算机教学部） | D9: 计算机科学与技术 | E9: 计科221 | F9: 已完成 | G9: 2025-09-04 10:51 | H9: 已完成 | I9: 2025-09-04 10:51 | J9: 已完成 | K9: 2025-09-04 23:45 | L9: 已完成 | M9: 2025-09-05 14:48 | N9: 已完成 | O9: 2025-09-05 14:49 | P9: 已完成 | Q9: 2025-09-05 14:52 | R9: 已完成 | S9: 2025-09-05 15:19 | T9: 已完成 | U9: 2025-09-05 15:37 | V9: 已完成 | W9: 2025-09-05 15:41 | X9: 已完成 | Y9: 2025-09-11 08:08 | Z9: 已完成 | AA9: 2025-09-11 08:18 | AB9: 已完成 | AC9: 2025-09-13 09:00 | AD9: 已完成 | AE9: 2025-09-13 09:03 | AF9: 已完成 | AG9: 2025-09-13 09:05 | AH9: 已完成 | AI9: 2025-09-13 09:09 | AJ9: 已完成 | AK9: 2025-09-18 08:33 | AL9: 已完成 | AM9: 2025-09-18 08:38 | AN9: 已完成 | AO9: 2025-09-18 08:45 | AP9: 已完成 | AQ9: 2025-09-18 08:51 | AR9: 已完成 | AS9: 2025-09-18 08:59 | AT9: 已完成 | AU9: 2025-09-18 09:04 | AV9: 已完成 | AW9: 2025-09-18 09:09 | AX9: 已完成 | AY9: 2025-09-18 09:32 | AZ9: 已完成 | BA9: 2025-09-24 10:46 | BB9: 已完成 | BC9: 2025-09-25 08:24 | BD9: 已完成 | BE9: 2025-09-25 08:25 | BF9: 已完成 | BG9: 2025-10-13 21:03 | BH9: 已完成 | BI9: 2025-09-25 08:30 | BJ9: 已完成 | BK9: 2025-09-25 08:34 | BL9: 已完成 | BM9: 2025-09-25 08:39 | BN9: 已完成 | BO9: 2025-09-25 08:43 | BP9: 已完成 | BQ9: 2025-09-25 08:50 | BR9: 已完成 | BS9: 2025-09-25 09:02 | BT9: 已完成 | BU9: 2025-09-25 09:04 | BV9: 已完成 | BW9: 2025-09-25 09:09 | BX9: 已完成 | BY9: 2025-12-31 19:28 | BZ9: 已完成 | CA9: 2026-01-15 17:39
A10: 陈创东 | B10: 2022210333 | C10: 计算机与信息工程学院（大学计算机教学部） | D10: 计算机科学与技术 | E10: 计科221 | F10: 已完成 | G10: 2025-09-04 08:10 | H10: 已完成 | I10: 2025-09-04 08:10 | J10: 已完成 | K10: 2025-09-04 08:10 | L10: 已完成 | M10: 2025-09-09 22:18 | N10: 已完成 | O10: 2025-09-09 22:20 | P10: 已完成 | Q10: 2025-09-09 22:20 | R10: 已完成 | S10: 2025-09-04 09:10 | T10: 已完成 | U10: 2025-09-18 08:27 | V10: 已完成 | W10: 2025-09-04 09:25 | X10: 已完成 | Y10: 2025-09-27 17:40 | Z10: 已完成 | AA10: 2025-09-27 17:53 | AB10: 已完成 | AC10: 2025-09-27 18:02 | AD10: 已完成 | AE10: 2025-09-27 18:04 | AF10: 已完成 | AG10: 2025-10-08 18:42 | AH10: 已完成 | AI10: 2025-10-13 10:41 | AJ10: 已完成 | AK10: 2025-10-13 10:43 | AL10: 已完成 | AM10: 2025-10-13 10:53 | AN10: 已完成 | AO10: 2025-10-14 17:08 | AP10: 已完成 | AQ10: 2025-10-13 10:59 | AR10: 已完成 | AS10: 2025-10-14 17:08 | AT10: 已完成 | AU10: 2025-10-14 17:13 | AV10: 已完成 | AW10: 2025-10-14 17:13 | AX10: 已完成 | AY10: 2025-10-14 17:17 | AZ10: 已完成 | BA10: 2025-10-14 17:18 | BB10: 已完成 | BC10: 2025-10-23 08:09 | BD10: 已完成 | BE10: 2025-10-23 08:11 | BF10: 已完成 | BG10: 2025-10-23 08:19 | BH10: 已完成 | BI10: 2025-10-23 08:20 | BJ10: 已完成 | BK10: 2025-10-23 08:24 | BL10: 已完成 | BM10: 2025-10-23 08:24 | BN10: 已完成 | BO10: 2025-10-23 08:27 | BP10: 已完成 | BQ10: 2025-10-23 08:28 | BR10: 已完成 | BS10: 2025-10-23 08:32 | BT10: 已完成 | BU10: 2025-10-23 08:33 | BV10: 已完成 | BW10: 2025-10-23 08:37 | BX10: 已完成 | BY10: 2025-12-31 19:32 | BZ10: 已完成 | CA10: 2026-01-15 17:46
A11: 程纪阳 | B11: 2022210334 | C11: 计算机与信息工程学院（大学计算机教学部） | D11: 计算机科学与技术 | E11: 计科221 | F11: 已完成 | G11: 2025-09-04 08:09 | H11: 已完成 | I11: 2025-09-04 08:09 | J11: 已完成 | K11: 2025-09-04 08:09 | L11: 已完成 | M11: 2025-09-04 08:13 | N11: 已完成 | O11: 2025-09-04 08:13 | P11: 已完成 | Q11: 2025-09-08 10:13 | R11: 已完成 | S11: 2025-09-27 17:22 | T11: 已完成 | U11: 2025-09-27 17:23 | V11: 已完成 | W11: 2025-09-27 17:27 | X11: 已完成 | Y11: 2025-09-27 17:27 | Z11: 已完成 | AA11: 2025-09-27 17:35 | AB11: 已完成 | AC11: 2025-09-27 17:40 | AD11: 已完成 | AE11: 2025-09-27 17:43 | AF11: 已完成 | AG11: 2025-09-27 17:43 | AH11: 已完成 | AI11: 2025-09-27 17:47 | AJ11: 已完成 | AK11: 2025-09-27 17:47 | AL11: 已完成 | AM11: 2025-09-27 17:51 | AN11: 已完成 | AO11: 2025-09-27 17:52 | AP11: 已完成 | AQ11: 2025-09-27 17:55 | AR11: 已完成 | AS11: 2025-10-09 07:58 | AT11: 已完成 | AU11: 2025-11-21 12:37 | AV11: 已完成 | AW11: 2025-11-21 12:39 | AX11: 已完成 | AY11: 2025-11-21 12:45 | AZ11: 已完成 | BA11: 2025-11-21 12:49 | BB11: 已完成 | BC11: 2025-11-21 12:56 | BD11: 已完成 | BE11: 2025-11-21 13:20 | BF11: 已完成 | BG11: 2025-11-21 13:25 | BH11: 已完成 | BI11: 2025-11-21 13:31 | BJ11: 已完成 | BK11: 2025-11-21 13:34 | BL11: 已完成 | BM11: 2025-11-21 13:36 | BN11: 已完成 | BO11: 2025-11-21 13:39 | BP11: 已完成 | BQ11: 2025-11-21 13:41 | BR11: 已完成 | BS11: 2025-11-21 13:44 | BT11: 已完成 | BU11: 2025-11-21 13:45 | BV11: 已完成 | BW11: 2025-11-21 13:49 | BX11: 已完成 | BY11: 2025-12-31 19:31 | BZ11: 已完成 | CA11: 2026-01-15 17:42
A12: 程梦圆 | B12: 2022210335 | C12: 计算机与信息工程学院（大学计算机教学部） | D12: 计算机科学与技术 | E12: 计科221 | F12: 已完成 | G12: 2025-09-28 07:11 | H12: 已完成 | I12: 2025-09-28 07:11 | J12: 已完成 | K12: 2025-09-28 07:11 | L12: 已完成 | M12: 2025-09-28 07:58 | N12: 已完成 | O12: 2025-09-28 07:58 | P12: 已完成 | Q12: 2025-09-28 08:00 | R12: 已完成 | S12: 2025-09-28 08:16 | T12: 已完成 | U12: 2025-09-28 08:23 | V12: 已完成 | W12: 2025-09-28 10:07 | X12: 已完成 | Y12: 2025-09-28 10:25 | Z12: 已完成 | AA12: 2025-09-28 10:17 | AB12: 已完成 | AC12: 2025-09-28 10:25 | AD12: 已完成 | AE12: 2025-09-28 10:28 | AF12: 已完成 | AG12: 2025-09-28 10:29 | AH12: 已完成 | AI12: 2025-09-28 10:33 | AJ12: 已完成 | AK12: 2025-09-28 10:40 | AL12: 已完成 | AM12: 2025-09-28 10:38 | AN12: 已完成 | AO12: 2025-09-28 10:40 | AP12: 已完成 | AQ12: 2025-09-28 10:43 | AR12: 已完成 | AS12: 2025-09-28 10:46 | AT12: 已完成 | AU12: 2025-09-28 10:49 | AV12: 已完成 | AW12: 2025-09-28 10:54 | AX12: 已完成 | AY12: 2025-09-28 10:58 | AZ12: 已完成 | BA12: 2025-09-28 11:13 | BB12: 已完成 | BC12: 2025-09-28 11:17 | BD12: 已完成 | BE12: 2025-09-28 11:18 | BF12: 已完成 | BG12: 2025-11-19 21:03 | BH12: 已完成 | BI12: 2025-09-28 11:23 | BJ12: 已完成 | BK12: 2025-09-28 11:25 | BL12: 已完成 | BM12: 2025-09-28 11:34 | BN12: 已完成 | BO12: 2025-09-28 11:46 | BP12: 已完成 | BQ12: 2025-09-28 11:47 | BR12: 已完成 | BS12: 2025-09-28 11:49 | BT12: 已完成 | BU12: 2025-09-28 11:50 | BV12: 已完成 | BW12: 2025-09-28 11:52 | BX12: 已完成 | BY12: 2026-01-09 19:22 | BZ12: 已完成 | CA12: 2026-01-15 17:41
A13: 邓慧茹 | B13: 2022210337 | C13: 计算机与信息工程学院（大学计算机教学部） | D13: 计算机科学与技术 | E13: 计科221 | F13: 已完成 | G13: 2025-09-04 08:09 | H13: 已完成 | I13: 2025-09-10 10:30 | J13: 已完成 | K13: 2025-09-10 10:30 | L13: 已完成 | M13: 2025-09-04 08:17 | N13: 已完成 | O13: 2025-09-10 10:30 | P13: 已完成 | Q13: 2025-09-10 10:40 | R13: 已完成 | S13: 2025-09-18 08:04 | T13: 已完成 | U13: 2025-09-18 08:06 | V13: 已完成 | W13: 2025-09-18 08:13 | X13: 已完成 | Y13: 2025-09-18 08:14 | Z13: 已完成 | AA13: 2025-09-28 10:18 | AB13: 已完成 | AC13: 2025-09-28 10:27 | AD13: 已完成 | AE13: 2025-09-28 10:31 | AF13: 已完成 | AG13: 2025-09-28 10:50 | AH13: 已完成 | AI13: 2025-09-28 10:57 | AJ13: 已完成 | AK13: 2025-09-28 11:07 | AL13: 已完成 | AM13: 2025-09-28 11:13 | AN13: 已完成 | AO13: 2025-09-28 11:26 | AP13: 已完成 | AQ13: 2025-09-28 11:31 | AR13: 已完成 | AS13: 2025-09-28 11:35 | AT13: 已完成 | AU13: 2025-09-28 11:41 | AV13: 已完成 | AW13: 2025-09-29 10:33 | AX13: 已完成 | AY13: 2025-09-29 10:40 | AZ13: 已完成 | BA13: 2025-10-09 08:15 | BB13: 已完成 | BC13: 2025-10-09 08:22 | BD13: 已完成 | BE13: 2025-10-09 08:30 | BF13: 已完成 | BG13: 2025-10-23 08:10 | BH13: 已完成 | BI13: 2025-10-09 08:44 | BJ13: 已完成 | BK13: 2025-10-09 08:48 | BL13: 已完成 | BM13: 2025-10-09 08:51 | BN13: 已完成 | BO13: 2025-10-09 08:55 | BP13: 已完成 | BQ13: 2025-10-09 09:06 | BR13: 已完成 | BS13: 2025-10-09 09:11 | BT13: 已完成 | BU13: 2025-10-09 09:18 | BV13: 已完成 | BW13: 2025-10-23 08:20 | BX13: 已完成 | BY13: 2026-01-09 20:27 | BZ13: 未完成
A14: 丁玉耀 | B14: 2022210338 | C14: 计算机与信息工程学院（大学计算机教学部） | D14: 计算机科学与技术 | E14: 计科221 | F14: 已完成 | G14: 2026-01-10 11:01 | H14: 已完成 | I14: 2026-01-10 11:01 | J14: 已完成 | K14: 2026-01-10 11:02 | L14: 已完成 | M14: 2026-01-10 11:06 | N14: 已完成 | O14: 2026-01-10 11:06 | P14: 已完成 | Q14: 2026-01-10 11:06 | R14: 已完成 | S14: 2026-01-10 11:09 | T14: 已完成 | U14: 2026-01-10 11:10 | V14: 已完成 | W14: 2026-01-10 11:13 | X14: 已完成 | Y14: 2026-01-10 11:15 | Z14: 已完成 | AA14: 2026-01-10 11:24 | AB14: 已完成 | AC14: 2026-01-10 11:25 | AD14: 已完成 | AE14: 2026-01-10 11:27 | AF14: 已完成 | AG14: 2026-01-10 11:28 | AH14: 已完成 | AI14: 2026-01-10 11:31 | AJ14: 已完成 | AK14: 2026-01-10 11:31 | AL14: 已完成 | AM14: 2026-01-10 11:34 | AN14: 已完成 | AO14: 2026-01-10 11:34 | AP14: 已完成 | AQ14: 2026-01-10 11:36 | AR14: 已完成 | AS14: 2026-01-10 11:37 | AT14: 已完成 | AU14: 2026-01-10 11:40 | AV14: 已完成 | AW14: 2026-01-10 11:40 | AX14: 已完成 | AY14: 2026-01-10 11:43 | AZ14: 已完成 | BA14: 2026-01-10 11:43 | BB14: 已完成 | BC14: 2026-01-10 11:47 | BD14: 已完成 | BE14: 2026-01-10 11:48 | BF14: 已完成 | BG14: 2026-01-10 11:50 | BH14: 已完成 | BI14: 2026-01-10 11:50 | BJ14: 已完成 | BK14: 2026-01-10 11:52 | BL14: 已完成 | BM14: 2026-01-10 11:54 | BN14: 已完成 | BO14: 2026-01-10 11:56 | BP14: 已完成 | BQ14: 2026-01-10 11:57 | BR14: 已完成 | BS14: 2026-01-10 11:59 | BT14: 已完成 | BU14: 2026-01-10 12:00 | BV14: 已完成 | BW14: 2026-01-10 12:02 | BX14: 已完成 | BY14: 2026-01-10 12:03 | BZ14: 已完成 | CA14: 2026-01-15 18:15
A15: 范鑫蕊 | B15: 2022210339 | C15: 计算机与信息工程学院（大学计算机教学部） | D15: 计算机科学与技术 | E15: 计科221 | F15: 已完成 | G15: 2025-09-07 22:16 | H15: 已完成 | I15: 2025-09-07 22:16 | J15: 已完成 | K15: 2025-09-07 22:17 | L15: 已完成 | M15: 2025-09-08 09:58 | N15: 已完成 | O15: 2025-09-08 09:59 | P15: 已完成 | Q15: 2025-09-08 10:01 | R15: 已完成 | S15: 2025-09-10 10:54 | T15: 已完成 | U15: 2025-09-10 10:54 | V15: 已完成 | W15: 2025-09-11 08:13 | X15: 已完成 | Y15: 2025-09-11 08:15 | Z15: 已完成 | AA15: 2025-09-18 08:07 | AB15: 已完成 | AC15: 2025-09-18 08:10 | AD15: 已完成 | AE15: 2025-09-18 08:14 | AF15: 已完成 | AG15: 2025-09-18 09:31 | AH15: 已完成 | AI15: 2025-09-18 09:37 | AJ15: 已完成 | AK15: 2025-09-18 09:38 | AL15: 已完成 | AM15: 2025-09-24 08:25 | AN15: 已完成 | AO15: 2025-09-24 08:26 | AP15: 已完成 | AQ15: 2025-09-24 08:33 | AR15: 已完成 | AS15: 2025-09-24 08:34 | AT15: 已完成 | AU15: 2025-09-24 08:40 | AV15: 已完成 | AW15: 2025-09-24 09:20 | AX15: 已完成 | AY15: 2025-09-28 10:03 | AZ15: 已完成 | BA15: 2025-09-28 10:13 | BB15: 已完成 | BC15: 2025-09-28 10:20 | BD15: 已完成 | BE15: 2025-09-28 10:21 | BF15: 已完成 | BG15: 2025-10-22 11:37 | BH15: 已完成 | BI15: 2025-09-28 10:26 | BJ15: 已完成 | BK15: 2025-10-09 08:20 | BL15: 已完成 | BM15: 2025-10-13 09:59 | BN15: 已完成 | BO15: 2025-10-09 08:27 | BP15: 已完成 | BQ15: 2025-10-13 10:00 | BR15: 已完成 | BS15: 2025-10-13 10:04 | BT15: 已完成 | BU15: 2025-10-13 10:10 | BV15: 已完成 | BW15: 2025-10-13 10:14 | BX15: 已完成 | BY15: 2026-01-16 14:06 | BZ15: 已完成 | CA15: 2026-01-16 14:06
A16: 高恩鹏 | B16: 2022210342 | C16: 计算机与信息工程学院（大学计算机教学部） | D16: 计算机科学与技术 | E16: 计科221 | F16: 已完成 | G16: 2025-09-04 08:16 | H16: 已完成 | I16: 2025-09-04 08:17 | J16: 已完成 | K16: 2025-09-04 08:24 | L16: 已完成 | M16: 2025-09-10 11:03 | N16: 已完成 | O16: 2025-09-04 10:49 | P16: 已完成 | Q16: 2025-09-10 11:03 | R16: 已完成 | S16: 2025-09-27 17:37 | T16: 已完成 | U16: 2025-09-27 18:26 | V16: 已完成 | W16: 2025-09-27 18:32 | X16: 已完成 | Y16: 2025-09-27 18:43 | Z16: 已完成 | AA16: 2025-09-27 19:01 | AB16: 已完成 | AC16: 2025-09-28 10:34 | AD16: 已完成 | AE16: 2025-11-10 18:06 | AF16: 已完成 | AG16: 2025-09-04 08:23 | AH16: 已完成 | AI16: 2025-11-10 18:13 | AJ16: 已完成 | AK16: 2025-11-10 18:17 | AL16: 已完成 | AM16: 2025-11-10 18:22 | AN16: 已完成 | AO16: 2025-11-10 18:22 | AP16: 已完成 | AQ16: 2025-11-10 18:27 | AR16: 已完成 | AS16: 2025-09-04 10:49 | AT16: 已完成 | AU16: 2025-11-10 18:34 | AV16: 已完成 | AW16: 2025-11-10 18:34 | AX16: 已完成 | AY16: 2025-11-10 18:40 | AZ16: 已完成 | BA16: 2025-11-10 18:50 | BB16: 已完成 | BC16: 2025-11-10 18:56 | BD16: 已完成 | BE16: 2025-11-10 19:05 | BF16: 已完成 | BG16: 2025-11-10 19:03 | BH16: 已完成 | BI16: 2025-11-10 19:05 | BJ16: 已完成 | BK16: 2025-11-10 19:08 | BL16: 已完成 | BM16: 2025-11-10 19:17 | BN16: 已完成 | BO16: 2025-11-10 19:32 | BP16: 已完成 | BQ16: 2025-11-10 19:37 | BR16: 已完成 | BS16: 2025-11-10 19:41 | BT16: 已完成 | BU16: 2025-11-10 19:43 | BV16: 已完成 | BW16: 2025-11-10 19:48 | BX16: 已完成 | BY16: 2026-01-01 11:03 | BZ16: 已完成 | CA16: 2026-01-15 17:33
A17: 关雪艳 | B17: 2022210343 | C17: 计算机与信息工程学院（大学计算机教学部） | D17: 计算机科学与技术 | E17: 计科221 | F17: 已完成 | G17: 2025-09-04 08:17 | H17: 已完成 | I17: 2025-09-04 08:17 | J17: 已完成 | K17: 2025-09-04 08:17 | L17: 已完成 | M17: 2025-09-04 08:22 | N17: 已完成 | O17: 2025-09-04 08:28 | P17: 已完成 | Q17: 2025-09-10 10:17 | R17: 已完成 | S17: 2025-09-10 10:21 | T17: 已完成 | U17: 2025-09-18 08:05 | V17: 已完成 | W17: 2025-09-18 08:12 | X17: 已完成 | Y17: 2025-09-18 08:15 | Z17: 已完成 | AA17: 2025-09-18 08:21 | AB17: 已完成 | AC17: 2025-09-18 08:21 | AD17: 已完成 | AE17: 2025-09-18 08:24 | AF17: 已完成 | AG17: 2025-09-18 08:28 | AH17: 已完成 | AI17: 2025-09-18 08:31 | AJ17: 已完成 | AK17: 2025-09-18 08:34 | AL17: 已完成 | AM17: 2025-09-28 10:18 | AN17: 已完成 | AO17: 2025-09-28 10:20 | AP17: 已完成 | AQ17: 2025-09-28 10:23 | AR17: 已完成 | AS17: 2025-09-28 10:25 | AT17: 已完成 | AU17: 2025-09-28 10:28 | AV17: 已完成 | AW17: 2025-09-28 10:29 | AX17: 已完成 | AY17: 2025-09-28 10:33 | AZ17: 已完成 | BA17: 2025-09-28 10:46 | BB17: 已完成 | BC17: 2025-09-28 10:50 | BD17: 已完成 | BE17: 2025-09-28 11:19 | BF17: 已完成 | BG17: 2025-11-03 12:26 | BH17: 已完成 | BI17: 2025-09-28 11:23 | BJ17: 已完成 | BK17: 2025-09-28 11:26 | BL17: 已完成 | BM17: 2025-09-28 11:50 | BN17: 已完成 | BO17: 2025-09-29 10:39 | BP17: 已完成 | BQ17: 2025-09-29 10:47 | BR17: 已完成 | BS17: 2025-09-29 10:49 | BT17: 已完成 | BU17: 2025-09-29 11:03 | BV17: 已完成 | BW17: 2025-09-29 11:05 | BX17: 已完成 | BY17: 2026-01-10 08:06 | BZ17: 已完成 | CA17: 2026-01-15 17:33
A18: 郭新杰 | B18: 2022210344 | C18: 计算机与信息工程学院（大学计算机教学部） | D18: 计算机科学与技术 | E18: 计科221 | F18: 已完成 | G18: 2025-09-05 17:53 | H18: 已完成 | I18: 2025-09-05 18:00 | J18: 已完成 | K18: 2025-09-06 16:40 | L18: 已完成 | M18: 2025-09-04 08:17 | N18: 已完成 | O18: 2025-09-06 16:40 | P18: 已完成 | Q18: 2025-09-10 10:15 | R18: 已完成 | S18: 2025-09-10 10:22 | T18: 已完成 | U18: 2025-09-10 10:25 | V18: 已完成 | W18: 2025-09-10 11:34 | X18: 已完成 | Y18: 2025-09-10 11:44 | Z18: 已完成 | AA18: 2025-09-15 10:11 | AB18: 已完成 | AC18: 2025-09-15 10:12 | AD18: 已完成 | AE18: 2025-09-18 08:16 | AF18: 已完成 | AG18: 2025-09-24 10:06 | AH18: 已完成 | AI18: 2025-09-24 10:15 | AJ18: 已完成 | AK18: 2025-09-25 08:16 | AL18: 已完成 | AM18: 2025-09-25 08:22 | AN18: 已完成 | AO18: 2025-09-25 08:39 | AP18: 已完成 | AQ18: 2025-09-25 08:43 | AR18: 已完成 | AS18: 2025-09-28 10:09 | AT18: 已完成 | AU18: 2025-09-28 10:22 | AV18: 已完成 | AW18: 2025-09-28 10:24 | AX18: 已完成 | AY18: 2025-09-28 10:33 | AZ18: 已完成 | BA18: 2025-10-09 08:45 | BB18: 已完成 | BC18: 2025-10-09 08:52 | BD18: 已完成 | BE18: 2025-10-16 09:23 | BF18: 已完成 | BG18: 2025-10-22 10:09 | BH18: 已完成 | BI18: 2025-10-22 10:11 | BJ18: 已完成 | BK18: 2025-10-22 10:30 | BL18: 已完成 | BM18: 2025-10-22 10:32 | BN18: 已完成 | BO18: 2025-10-22 10:35 | BP18: 已完成 | BQ18: 2025-10-22 10:39 | BR18: 已完成 | BS18: 2025-10-22 11:24 | BT18: 已完成 | BU18: 2025-10-22 11:29 | BV18: 已完成 | BW18: 2025-10-23 08:08 | BX18: 已完成 | BY18: 2026-01-01 11:26 | BZ18: 已完成 | CA18: 2026-01-15 19:02
A19: 洪晓瑞 | B19: 2022210346 | C19: 计算机与信息工程学院（大学计算机教学部） | D19: 计算机科学与技术 | E19: 计科221 | F19: 已完成 | G19: 2025-09-04 08:56 | H19: 已完成 | I19: 2025-09-04 08:56 | J19: 已完成 | K19: 2025-09-04 08:56 | L19: 已完成 | M19: 2025-09-10 10:06 | N19: 已完成 | O19: 2025-09-04 08:57 | P19: 已完成 | Q19: 2025-09-11 07:50 | R19: 已完成 | S19: 2025-09-11 08:00 | T19: 已完成 | U19: 2025-09-18 08:02 | V19: 已完成 | W19: 2025-09-18 08:07 | X19: 已完成 | Y19: 2025-09-18 08:25 | Z19: 已完成 | AA19: 2025-09-18 08:36 | AB19: 已完成 | AC19: 2025-11-10 22:23 | AD19: 已完成 | AE19: 2025-11-10 22:27 | AF19: 已完成 | AG19: 2025-11-10 22:29 | AH19: 已完成 | AI19: 2025-11-10 22:32 | AJ19: 已完成 | AK19: 2025-11-10 22:39 | AL19: 已完成 | AM19: 2025-11-10 22:42 | AN19: 已完成 | AO19: 2025-11-10 22:44 | AP19: 已完成 | AQ19: 2025-11-10 22:48 | AR19: 已完成 | AS19: 2025-11-10 22:56 | AT19: 已完成 | AU19: 2025-11-10 22:59 | AV19: 已完成 | AW19: 2025-11-10 23:00 | AX19: 已完成 | AY19: 2025-11-10 23:03 | AZ19: 已完成 | BA19: 2025-11-10 23:04 | BB19: 已完成 | BC19: 2025-11-10 23:07 | BD19: 已完成 | BE19: 2025-11-10 23:10 | BF19: 已完成 | BG19: 2025-11-10 23:12 | BH19: 已完成 | BI19: 2025-11-10 23:15 | BJ19: 已完成 | BK19: 2025-11-10 23:18 | BL19: 已完成 | BM19: 2025-11-10 23:18 | BN19: 已完成 | BO19: 2025-11-10 23:20 | BP19: 已完成 | BQ19: 2025-11-10 23:21 | BR19: 已完成 | BS19: 2025-11-10 23:23 | BT19: 已完成 | BU19: 2025-11-10 23:24 | BV19: 已完成 | BW19: 2025-11-10 23:26 | BX19: 已完成 | BY19: 2026-01-09 19:17 | BZ19: 已完成 | CA19: 2026-01-15 18:58
A20: 胡步兴 | B20: 2022210347 | C20: 计算机与信息工程学院（大学计算机教学部） | D20: 计算机科学与技术 | E20: 计科221 | F20: 已完成 | G20: 2025-09-08 10:02 | H20: 已完成 | I20: 2025-09-10 10:24 | J20: 已完成 | K20: 2025-09-10 10:24 | L20: 已完成 | M20: 2025-09-10 10:30 | N20: 已完成 | O20: 2025-09-10 10:31 | P20: 已完成 | Q20: 2025-09-10 10:39 | R20: 已完成 | S20: 2025-09-12 20:02 | T20: 已完成 | U20: 2025-09-12 20:02 | V20: 已完成 | W20: 2025-09-12 20:05 | X20: 已完成 | Y20: 2025-09-12 20:06 | Z20: 已完成 | AA20: 2025-09-18 08:04 | AB20: 已完成 | AC20: 2025-09-18 08:06 | AD20: 已完成 | AE20: 2025-09-18 08:10 | AF20: 已完成 | AG20: 2025-09-27 17:38 | AH20: 已完成 | AI20: 2025-09-27 19:21 | AJ20: 已完成 | AK20: 2025-09-27 19:23 | AL20: 已完成 | AM20: 2025-09-27 19:26 | AN20: 已完成 | AO20: 2025-09-27 19:26 | AP20: 已完成 | AQ20: 2025-09-27 19:29 | AR20: 已完成 | AS20: 2025-09-27 19:31 | AT20: 已完成 | AU20: 2025-09-27 19:34 | AV20: 已完成 | AW20: 2025-09-27 19:38 | AX20: 已完成 | AY20: 2025-09-27 19:46 | AZ20: 已完成 | BA20: 2025-09-27 19:46 | BB20: 已完成 | BC20: 2025-09-28 10:23 | BD20: 已完成 | BE20: 2025-09-28 10:23 | BF20: 已完成 | BG20: 2025-10-16 08:49 | BH20: 已完成 | BI20: 2025-09-28 10:33 | BJ20: 已完成 | BK20: 2025-09-28 10:37 | BL20: 已完成 | BM20: 2025-09-28 10:37 | BN20: 已完成 | BO20: 2025-09-28 10:58 | BP20: 已完成 | BQ20: 2025-09-28 11:49 | BR20: 已完成 | BS20: 2025-10-09 08:24 | BT20: 已完成 | BU20: 2025-10-09 08:28 | BV20: 已完成 | BW20: 2025-10-09 08:30 | BX20: 已完成 | BY20: 2026-01-10 14:59 | BZ20: 已完成 | CA20: 2026-01-15 21:11
A21: 胡昊泱 | B21: 2022210348 | C21: 计算机与信息工程学院（大学计算机教学部） | D21: 计算机科学与技术 | E21: 计科221 | F21: 已完成 | G21: 2025-09-10 10:39 | H21: 已完成 | I21: 2025-09-10 10:41 | J21: 已完成 | K21: 2025-09-10 10:41 | L21: 已完成 | M21: 2025-09-10 10:47 | N21: 已完成 | O21: 2025-09-04 08:38 | P21: 已完成 | Q21: 2025-09-04 08:08 | R21: 已完成 | S21: 2025-09-11 07:58 | T21: 已完成 | U21: 2025-09-11 07:58 | V21: 已完成 | W21: 2025-09-11 08:04 | X21: 已完成 | Y21: 2025-09-13 21:04 | Z21: 已完成 | AA21: 2025-09-18 08:13 | AB21: 已完成 | AC21: 2025-09-18 08:13 | AD21: 已完成 | AE21: 2025-09-18 08:22 | AF21: 已完成 | AG21: 2025-09-27 17:17 | AH21: 已完成 | AI21: 2025-09-27 17:23 | AJ21: 已完成 | AK21: 2025-09-27 17:23 | AL21: 已完成 | AM21: 2025-09-28 10:33 | AN21: 已完成 | AO21: 2025-10-09 08:33 | AP21: 已完成 | AQ21: 2025-10-09 08:36 | AR21: 已完成 | AS21: 2025-10-09 08:40 | AT21: 已完成 | AU21: 2025-10-09 08:43 | AV21: 已完成 | AW21: 2025-10-09 08:51 | AX21: 已完成 | AY21: 2025-10-09 08:54 | AZ21: 已完成 | BA21: 2025-10-09 09:06 | BB21: 已完成 | BC21: 2025-10-09 09:16 | BD21: 已完成 | BE21: 2025-10-09 09:20 | BF21: 已完成 | BG21: 2025-10-16 08:30 | BH21: 已完成 | BI21: 2025-10-16 08:30 | BJ21: 已完成 | BK21: 2025-10-16 08:32 | BL21: 已完成 | BM21: 2025-10-16 08:33 | BN21: 已完成 | BO21: 2025-10-16 08:35 | BP21: 已完成 | BQ21: 2025-10-16 08:37 | BR21: 已完成 | BS21: 2025-10-16 08:40 | BT21: 已完成 | BU21: 2025-10-16 08:40 | BV21: 已完成 | BW21: 2025-10-16 08:42 | BX21: 已完成 | BY21: 2026-01-09 19:20 | BZ21: 已完成 | CA21: 2026-01-15 18:01
A22: 季玮 | B22: 2022210351 | C22: 计算机与信息工程学院（大学计算机教学部） | D22: 计算机科学与技术 | E22: 计科221 | F22: 已完成 | G22: 2025-09-04 08:04 | H22: 已完成 | I22: 2025-09-04 08:08 | J22: 已完成 | K22: 2025-09-04 08:08 | L22: 已完成 | M22: 2025-09-10 10:06 | N22: 已完成 | O22: 2025-09-10 10:06 | P22: 已完成 | Q22: 2025-09-10 10:08 | R22: 已完成 | S22: 2025-09-11 07:43 | T22: 已完成 | U22: 2025-09-11 07:44 | V22: 已完成 | W22: 2025-09-11 07:47 | X22: 已完成 | Y22: 2025-09-11 08:08 | Z22: 已完成 | AA22: 2025-09-11 08:30 | AB22: 已完成 | AC22: 2025-09-18 07:51 | AD22: 已完成 | AE22: 2025-09-18 07:54 | AF22: 已完成 | AG22: 2025-09-18 07:55 | AH22: 已完成 | AI22: 2025-09-18 08:03 | AJ22: 已完成 | AK22: 2025-09-18 08:04 | AL22: 已完成 | AM22: 2025-09-18 08:13 | AN22: 已完成 | AO22: 2025-09-18 08:15 | AP22: 已完成 | AQ22: 2025-09-18 08:18 | AR22: 已完成 | AS22: 2025-09-28 10:33 | AT22: 已完成 | AU22: 2025-09-28 10:38 | AV22: 已完成 | AW22: 2025-09-28 10:39 | AX22: 已完成 | AY22: 2025-09-28 10:45 | AZ22: 已完成 | BA22: 2025-09-28 11:00 | BB22: 已完成 | BC22: 2025-10-27 10:20 | BD22: 已完成 | BE22: 2025-10-27 10:24 | BF22: 已完成 | BG22: 2025-10-27 10:27 | BH22: 已完成 | BI22: 2025-10-27 10:29 | BJ22: 已完成 | BK22: 2025-10-27 10:31 | BL22: 已完成 | BM22: 2025-10-27 10:33 | BN22: 已完成 | BO22: 2025-10-27 10:35 | BP22: 已完成 | BQ22: 2025-10-27 10:36 | BR22: 已完成 | BS22: 2025-10-27 10:38 | BT22: 已完成 | BU22: 2025-10-27 10:40 | BV22: 已完成 | BW22: 2025-10-27 10:44 | BX22: 已完成 | BY22: 2026-01-09 19:20 | BZ22: 已完成 | CA22: 2026-01-15 19:27
A23: 李宝航 | B23: 2022210359 | C23: 计算机与信息工程学院（大学计算机教学部） | D23: 计算机科学与技术 | E23: 计科221 | F23: 已完成 | G23: 2025-09-13 16:50 | H23: 已完成 | I23: 2025-09-13 16:51 | J23: 已完成 | K23: 2025-09-13 16:51 | L23: 已完成 | M23: 2025-09-13 19:15 | N23: 已完成 | O23: 2025-09-13 19:15 | P23: 已完成 | Q23: 2025-09-13 19:26 | R23: 已完成 | S23: 2025-11-03 09:59 | T23: 已完成 | U23: 2025-11-03 10:00 | V23: 已完成 | W23: 2025-11-03 10:03 | X23: 已完成 | Y23: 2025-11-03 10:03 | Z23: 已完成 | AA23: 2025-11-03 10:09 | AB23: 已完成 | AC23: 2025-11-03 10:10 | AD23: 已完成 | AE23: 2025-11-03 10:12 | AF23: 已完成 | AG23: 2025-11-03 10:13 | AH23: 已完成 | AI23: 2025-11-03 10:16 | AJ23: 已完成 | AK23: 2025-11-03 10:18 | AL23: 已完成 | AM23: 2025-11-03 10:21 | AN23: 已完成 | AO23: 2025-11-03 10:22 | AP23: 已完成 | AQ23: 2025-11-03 10:25 | AR23: 已完成 | AS23: 2025-11-03 10:28 | AT23: 已完成 | AU23: 2025-11-03 10:30 | AV23: 已完成 | AW23: 2025-11-03 10:32 | AX23: 已完成 | AY23: 2025-11-03 10:35 | AZ23: 已完成 | BA23: 2025-11-03 10:40 | BB23: 已完成 | BC23: 2025-11-03 10:44 | BD23: 已完成 | BE23: 2025-11-03 10:44 | BF23: 已完成 | BG23: 2025-11-03 10:47 | BH23: 已完成 | BI23: 2025-11-03 10:49 | BJ23: 已完成 | BK23: 2025-11-03 10:51 | BL23: 已完成 | BM23: 2025-11-03 10:51 | BN23: 已完成 | BO23: 2025-11-03 10:53 | BP23: 已完成 | BQ23: 2025-11-03 10:54 | BR23: 已完成 | BS23: 2025-11-03 10:56 | BT23: 已完成 | BU23: 2025-11-03 10:56 | BV23: 已完成 | BW23: 2025-11-03 10:59 | BX23: 已完成 | BY23: 2026-01-10 00:16 | BZ23: 已完成 | CA23: 2026-01-15 17:38
A24: 李浩 | B24: 2022210360 | C24: 计算机与信息工程学院（大学计算机教学部） | D24: 计算机科学与技术 | E24: 计科221 | F24: 已完成 | G24: 2025-09-09 23:08 | H24: 已完成 | I24: 2025-09-09 23:08 | J24: 已完成 | K24: 2025-09-09 23:08 | L24: 已完成 | M24: 2025-09-09 23:15 | N24: 已完成 | O24: 2025-09-04 08:11 | P24: 已完成 | Q24: 2025-09-09 23:18 | R24: 已完成 | S24: 2025-09-09 23:21 | T24: 已完成 | U24: 2025-09-09 23:22 | V24: 已完成 | W24: 2025-09-09 23:25 | X24: 已完成 | Y24: 2025-09-09 23:26 | Z24: 已完成 | AA24: 2025-09-10 10:06 | AB24: 已完成 | AC24: 2025-09-10 10:46 | AD24: 已完成 | AE24: 2025-09-18 07:56 | AF24: 已完成 | AG24: 2025-09-18 08:02 | AH24: 已完成 | AI24: 2025-09-18 08:06 | AJ24: 已完成 | AK24: 2025-09-18 08:06 | AL24: 已完成 | AM24: 2025-09-18 08:09 | AN24: 已完成 | AO24: 2025-09-18 08:18 | AP24: 已完成 | AQ24: 2025-09-25 08:17 | AR24: 已完成 | AS24: 2025-09-25 08:18 | AT24: 已完成 | AU24: 2025-09-25 08:21 | AV24: 已完成 | AW24: 2025-09-28 10:07 | AX24: 已完成 | AY24: 2025-09-26 16:43 | AZ24: 已完成 | BA24: 2025-09-04 08:12 | BB24: 已完成 | BC24: 2025-09-29 10:01 | BD24: 已完成 | BE24: 2025-09-29 10:08 | BF24: 已完成 | BG24: 2025-11-10 18:15 | BH24: 已完成 | BI24: 2025-10-09 08:03 | BJ24: 已完成 | BK24: 2025-10-09 08:07 | BL24: 已完成 | BM24: 2025-10-09 08:08 | BN24: 已完成 | BO24: 2025-10-09 08:12 | BP24: 已完成 | BQ24: 2025-10-09 08:13 | BR24: 已完成 | BS24: 2025-10-09 08:17 | BT24: 已完成 | BU24: 2025-10-09 08:19 | BV24: 已完成 | BW24: 2025-10-09 08:23 | BX24: 已完成 | BY24: 2025-12-31 19:25 | BZ24: 已完成 | CA24: 2026-01-15 17:36
A25: 李今朝 | B25: 2022210361 | C25: 计算机与信息工程学院（大学计算机教学部） | D25: 计算机科学与技术 | E25: 计科221 | F25: 已完成 | G25: 2025-09-04 08:02 | H25: 已完成 | I25: 2025-09-04 21:00 | J25: 已完成 | K25: 2025-09-04 21:02 | L25: 已完成 | M25: 2025-09-13 19:08 | N25: 已完成 | O25: 2025-09-13 19:10 | P25: 已完成 | Q25: 2025-09-04 08:45 | R25: 已完成 | S25: 2025-10-11 19:06 | T25: 已完成 | U25: 2025-10-11 19:08 | V25: 已完成 | W25: 2025-10-11 19:11 | X25: 已完成 | Y25: 2025-11-01 18:06 | Z25: 已完成 | AA25: 2025-11-01 18:12 | AB25: 已完成 | AC25: 2025-11-15 18:35 | AD25: 已完成 | AE25: 2025-11-15 18:38 | AF25: 已完成 | AG25: 2025-11-15 19:28 | AH25: 已完成 | AI25: 2025-11-15 19:32 | AJ25: 已完成 | AK25: 2025-11-15 19:41 | AL25: 已完成 | AM25: 2025-11-15 19:45 | AN25: 已完成 | AO25: 2025-11-15 19:50 | AP25: 已完成 | AQ25: 2025-11-15 19:52 | AR25: 已完成 | AS25: 2025-11-22 22:36 | AT25: 已完成 | AU25: 2025-11-22 22:39 | AV25: 已完成 | AW25: 2025-11-22 22:40 | AX25: 已完成 | AY25: 2025-11-22 22:44 | AZ25: 已完成 | BA25: 2025-11-22 22:44 | BB25: 已完成 | BC25: 2025-11-22 22:48 | BD25: 已完成 | BE25: 2025-11-22 22:55 | BF25: 已完成 | BG25: 2025-11-22 22:57 | BH25: 已完成 | BI25: 2025-11-22 23:01 | BJ25: 已完成 | BK25: 2025-11-23 00:25 | BL25: 已完成 | BM25: 2025-11-23 00:33 | BN25: 已完成 | BO25: 2025-11-23 00:35 | BP25: 已完成 | BQ25: 2025-11-23 00:36 | BR25: 已完成 | BS25: 2025-11-23 00:38 | BT25: 已完成 | BU25: 2025-11-23 00:40 | BV25: 已完成 | BW25: 2025-11-23 00:42 | BX25: 已完成 | BY25: 2026-01-09 19:17 | BZ25: 已完成 | CA25: 2026-01-15 18:56
... A32: 任奕凯 | B32: 2022210380 | C32: 计算机与信息工程学院（大学计算机教学部） | D32: 计算机科学与技术 | E32: 计科221 | F32: 已完成 | G32: 2025-09-07 15:36 | H32: 已完成 | I32: 2025-09-07 15:36 | J32: 已完成 | K32: 2025-09-07 15:37 | L32: 已完成 | M32: 2025-09-07 15:44 | N32: 已完成 | O32: 2025-09-04 10:12 | P32: 已完成 | Q32: 2025-09-07 19:03 | R32: 已完成 | S32: 2025-09-07 19:09 | T32: 已完成 | U32: 2025-09-07 19:54 | V32: 已完成 | W32: 2025-09-07 20:39 | X32: 已完成 | Y32: 2025-09-16 16:47 | Z32: 已完成 | AA32: 2025-09-16 16:59 | AB32: 已完成 | AC32: 2025-09-19 19:41 | AD32: 已完成 | AE32: 2025-09-28 10:23 | AF32: 已完成 | AG32: 2025-09-28 10:39 | AH32: 已完成 | AI32: 2025-09-28 10:46 | AJ32: 已完成 | AK32: 2025-09-28 10:47 | AL32: 已完成 | AM32: 2025-09-28 10:52 | AN32: 已完成 | AO32: 2025-09-28 10:53 | AP32: 已完成 | AQ32: 2025-09-28 10:57 | AR32: 已完成 | AS32: 2025-10-08 12:09 | AT32: 已完成 | AU32: 2025-10-08 12:16 | AV32: 已完成 | AW32: 2025-10-08 12:16 | AX32: 已完成 | AY32: 2025-10-08 12:22 | AZ32: 已完成 | BA32: 2025-10-08 12:44 | BB32: 已完成 | BC32: 2025-10-08 12:51 | BD32: 已完成 | BE32: 2025-10-08 12:51 | BF32: 已完成 | BG32: 2025-10-31 22:35 | BH32: 已完成 | BI32: 2025-10-08 12:56 | BJ32: 已完成 | BK32: 2025-10-08 12:59 | BL32: 已完成 | BM32: 2025-10-08 13:03 | BN32: 已完成 | BO32: 2025-10-08 13:06 | BP32: 已完成 | BQ32: 2025-10-08 13:11 | BR32: 已完成 | BS32: 2025-10-08 13:11 | BT32: 已完成 | BU32: 2025-10-08 13:11 | BV32: 已完成 | BW32: 2025-10-08 13:15 | BX32: 已完成 | BY32: 2026-01-06 22:08 | BZ32: 已完成 | CA32: 2026-01-15 18:00
A33: 阮珧 | B33: 2022210381 | C33: 计算机与信息工程学院（大学计算机教学部） | D33: 计算机科学与技术 | E33: 计科222 | F33: 已完成 | G33: 2025-09-10 10:25 | H33: 已完成 | I33: 2025-09-10 10:25 | J33: 已完成 | K33: 2025-09-10 10:26 | L33: 已完成 | M33: 2025-09-10 10:29 | N33: 已完成 | O33: 2025-09-10 10:30 | P33: 已完成 | Q33: 2025-09-10 10:44 | R33: 已完成 | S33: 2025-09-10 10:52 | T33: 已完成 | U33: 2025-09-10 10:54 | V33: 已完成 | W33: 2025-09-10 10:59 | X33: 已完成 | Y33: 2025-09-18 08:05 | Z33: 已完成 | AA33: 2025-10-31 16:25 | AB33: 已完成 | AC33: 2025-10-31 16:37 | AD33: 已完成 | AE33: 2025-10-31 16:36 | AF33: 已完成 | AG33: 2025-10-31 16:37 | AH33: 已完成 | AI33: 2025-10-31 16:43 | AJ33: 已完成 | AK33: 2025-10-31 16:46 | AL33: 已完成 | AM33: 2025-10-31 16:49 | AN33: 已完成 | AO33: 2025-10-31 17:02 | AP33: 已完成 | AQ33: 2025-10-31 17:04 | AR33: 已完成 | AS33: 2025-11-04 17:14 | AT33: 已完成 | AU33: 2025-11-04 17:17 | AV33: 已完成 | AW33: 2025-11-04 19:57 | AX33: 已完成 | AY33: 2025-11-04 20:00 | AZ33: 已完成 | BA33: 2025-11-04 20:18 | BB33: 已完成 | BC33: 2025-11-04 20:21 | BD33: 已完成 | BE33: 2025-11-04 20:22 | BF33: 已完成 | BG33: 2025-11-04 20:25 | BH33: 已完成 | BI33: 2025-11-04 20:42 | BJ33: 已完成 | BK33: 2025-11-04 20:44 | BL33: 已完成 | BM33: 2025-11-04 20:45 | BN33: 已完成 | BO33: 2025-11-04 20:47 | BP33: 已完成 | BQ33: 2025-11-04 20:50 | BR33: 已完成 | BS33: 2025-11-04 20:53 | BT33: 已完成 | BU33: 2025-11-04 20:59 | BV33: 已完成 | BW33: 2025-11-04 21:02 | BX33: 未完成 | BZ33: 未完成
A34: 孙嘉婧 | B34: 2022210384 | C34: 计算机与信息工程学院（大学计算机教学部） | D34: 计算机科学与技术 | E34: 计科222 | F34: 已完成 | G34: 2025-09-04 08:09 | H34: 已完成 | I34: 2025-09-04 08:09 | J34: 已完成 | K34: 2025-09-04 08:11 | L34: 已完成 | M34: 2025-09-07 22:25 | N34: 已完成 | O34: 2025-09-04 08:38 | P34: 已完成 | Q34: 2025-09-04 09:11 | R34: 已完成 | S34: 2025-09-10 10:25 | T34: 已完成 | U34: 2025-09-10 10:44 | V34: 已完成 | W34: 2025-09-11 08:31 | X34: 已完成 | Y34: 2025-09-11 08:32 | Z34: 已完成 | AA34: 2025-09-13 20:05 | AB34: 已完成 | AC34: 2025-09-13 20:10 | AD34: 已完成 | AE34: 2025-09-13 20:15 | AF34: 已完成 | AG34: 2025-09-13 20:15 | AH34: 已完成 | AI34: 2025-09-13 20:21 | AJ34: 已完成 | AK34: 2025-09-13 20:41 | AL34: 已完成 | AM34: 2025-09-13 20:46 | AN34: 已完成 | AO34: 2025-09-13 20:46 | AP34: 已完成 | AQ34: 2025-09-13 20:51 | AR34: 已完成 | AS34: 2025-09-13 20:52 | AT34: 已完成 | AU34: 2025-09-23 15:46 | AV34: 已完成 | AW34: 2025-09-23 15:47 | AX34: 已完成 | AY34: 2025-09-23 15:53 | AZ34: 已完成 | BA34: 2025-09-23 15:59 | BB34: 已完成 | BC34: 2025-09-23 16:06 | BD34: 已完成 | BE34: 2025-09-23 16:07 | BF34: 已完成 | BG34: 2025-10-18 23:06 | BH34: 已完成 | BI34: 2025-10-18 23:08 | BJ34: 已完成 | BK34: 2025-10-18 23:11 | BL34: 已完成 | BM34: 2025-10-18 23:12 | BN34: 已完成 | BO34: 2025-10-18 23:16 | BP34: 已完成 | BQ34: 2025-10-18 23:16 | BR34: 已完成 | BS34: 2025-10-18 23:20 | BT34: 已完成 | BU34: 2025-10-18 23:21 | BV34: 已完成 | BW34: 2025-10-18 23:25 | BX34: 已完成 | BY34: 2026-01-01 19:53 | BZ34: 已完成 | CA34: 2026-01-15 19:42
A35: 孙锦年 | B35: 2022210385 | C35: 计算机与信息工程学院（大学计算机教学部） | D35: 计算机科学与技术 | E35: 计科222 | F35: 已完成 | G35: 2025-09-04 08:09 | H35: 已完成 | I35: 2025-09-27 14:19 | J35: 已完成 | K35: 2025-09-27 14:20 | L35: 已完成 | M35: 2025-09-27 14:23 | N35: 已完成 | O35: 2025-09-27 14:24 | P35: 已完成 | Q35: 2025-09-27 14:24 | R35: 已完成 | S35: 2025-09-27 14:28 | T35: 已完成 | U35: 2025-09-27 14:30 | V35: 已完成 | W35: 2025-09-27 14:33 | X35: 已完成 | Y35: 2025-09-27 14:33 | Z35: 已完成 | AA35: 2025-09-27 14:39 | AB35: 已完成 | AC35: 2025-09-27 14:47 | AD35: 已完成 | AE35: 2025-09-27 14:50 | AF35: 已完成 | AG35: 2025-09-27 15:01 | AH35: 已完成 | AI35: 2025-09-27 15:05 | AJ35: 已完成 | AK35: 2025-09-27 15:09 | AL35: 已完成 | AM35: 2025-11-10 18:18 | AN35: 已完成 | AO35: 2025-11-10 18:23 | AP35: 已完成 | AQ35: 2025-11-10 18:25 | AR35: 已完成 | AS35: 2025-11-11 12:55 | AT35: 已完成 | AU35: 2025-11-11 13:25 | AV35: 已完成 | AW35: 2025-11-11 13:25 | AX35: 已完成 | AY35: 2025-11-11 13:28 | AZ35: 已完成 | BA35: 2025-11-11 13:29 | BB35: 已完成 | BC35: 2025-11-11 13:32 | BD35: 已完成 | BE35: 2025-11-11 13:47 | BF35: 已完成 | BG35: 2025-11-11 13:49 | BH35: 已完成 | BI35: 2025-11-13 11:20 | BJ35: 已完成 | BK35: 2025-11-13 11:23 | BL35: 已完成 | BM35: 2025-11-13 11:25 | BN35: 已完成 | BO35: 2025-11-13 11:27 | BP35: 已完成 | BQ35: 2025-11-13 11:27 | BR35: 已完成 | BS35: 2025-11-13 11:29 | BT35: 已完成 | BU35: 2025-11-13 11:30 | BV35: 已完成 | BW35: 2025-11-13 11:32 | BX35: 已完成 | BY35: 2026-01-01 12:06 | BZ35: 已完成 | CA35: 2026-01-15 17:41
A36: 唐蕊 | B36: 2022210387 | C36: 计算机与信息工程学院（大学计算机教学部） | D36: 计算机科学与技术 | E36: 计科222 | F36: 已完成 | G36: 2025-09-08 10:07 | H36: 已完成 | I36: 2025-09-08 10:07 | J36: 已完成 | K36: 2025-09-08 10:08 | L36: 已完成 | M36: 2025-09-08 10:14 | N36: 已完成 | O36: 2025-09-08 10:15 | P36: 已完成 | Q36: 2025-09-04 09:00 | R36: 已完成 | S36: 2025-09-08 10:19 | T36: 已完成 | U36: 2025-09-04 09:12 | V36: 已完成 | W36: 2025-09-08 10:44 | X36: 已完成 | Y36: 2025-09-11 08:11 | Z36: 已完成 | AA36: 2025-09-28 10:34 | AB36: 已完成 | AC36: 2025-09-28 10:36 | AD36: 已完成 | AE36: 2025-11-10 18:27 | AF36: 已完成 | AG36: 2025-11-10 18:43 | AH36: 已完成 | AI36: 2025-11-10 18:35 | AJ36: 已完成 | AK36: 2025-11-10 18:43 | AL36: 已完成 | AM36: 2025-11-10 18:49 | AN36: 已完成 | AO36: 2025-11-10 18:49 | AP36: 已完成 | AQ36: 2025-11-10 18:57 | AR36: 已完成 | AS36: 2025-11-10 18:59 | AT36: 已完成 | AU36: 2025-11-15 22:22 | AV36: 已完成 | AW36: 2025-11-15 22:29 | AX36: 已完成 | AY36: 2025-11-15 22:28 | AZ36: 已完成 | BA36: 2025-11-15 22:30 | BB36: 已完成 | BC36: 2025-11-15 22:36 | BD36: 已完成 | BE36: 2025-11-15 22:37 | BF36: 已完成 | BG36: 2025-11-15 22:41 | BH36: 已完成 | BI36: 2025-11-15 22:42 | BJ36: 已完成 | BK36: 2025-11-15 22:45 | BL36: 已完成 | BM36: 2025-11-15 22:46 | BN36: 已完成 | BO36: 2025-11-15 22:48 | BP36: 已完成 | BQ36: 2025-11-15 22:48 | BR36: 已完成 | BS36: 2025-11-15 22:52 | BT36: 已完成 | BU36: 2025-11-15 22:52 | BV36: 已完成 | BW36: 2025-11-15 22:54 | BX36: 已完成 | BY36: 2026-01-01 18:04 | BZ36: 已完成 | CA36: 2026-01-15 17:42
A37: 汪海洋 | B37: 2022210389 | C37: 计算机与信息工程学院（大学计算机教学部） | D37: 计算机科学与技术 | E37: 计科222 | F37: 已完成 | G37: 2025-09-10 10:02 | H37: 已完成 | I37: 2025-09-10 10:02 | J37: 已完成 | K37: 2025-09-10 10:02 | L37: 已完成 | M37: 2025-09-10 10:08 | N37: 已完成 | O37: 2025-09-10 10:08 | P37: 已完成 | Q37: 2025-09-10 10:09 | R37: 已完成 | S37: 2025-09-11 08:28 | T37: 已完成 | U37: 2025-09-11 08:29 | V37: 已完成 | W37: 2025-09-11 08:34 | X37: 已完成 | Y37: 2025-09-11 08:35 | Z37: 已完成 | AA37: 2025-09-11 08:45 | AB37: 已完成 | AC37: 2025-09-11 09:11 | AD37: 已完成 | AE37: 2025-09-18 07:56 | AF37: 已完成 | AG37: 2025-09-18 08:03 | AH37: 已完成 | AI37: 2025-09-28 10:07 | AJ37: 已完成 | AK37: 2025-09-28 10:10 | AL37: 已完成 | AM37: 2025-09-28 10:15 | AN37: 已完成 | AO37: 2025-09-28 10:18 | AP37: 已完成 | AQ37: 2025-09-28 10:23 | AR37: 已完成 | AS37: 2025-09-28 10:25 | AT37: 已完成 | AU37: 2025-09-28 10:31 | AV37: 已完成 | AW37: 2025-09-28 10:33 | AX37: 已完成 | AY37: 2025-09-28 10:39 | AZ37: 已完成 | BA37: 2025-09-28 10:42 | BB37: 已完成 | BC37: 2025-09-28 10:48 | BD37: 已完成 | BE37: 2025-09-28 10:50 | BF37: 已完成 | BG37: 2025-10-17 23:15 | BH37: 已完成 | BI37: 2025-09-28 10:55 | BJ37: 已完成 | BK37: 2025-09-28 10:58 | BL37: 已完成 | BM37: 2025-09-28 10:59 | BN37: 已完成 | BO37: 2025-09-28 11:03 | BP37: 已完成 | BQ37: 2025-09-28 11:04 | BR37: 已完成 | BS37: 2025-09-28 11:12 | BT37: 已完成 | BU37: 2025-09-28 11:12 | BV37: 已完成 | BW37: 2025-09-28 11:17 | BX37: 已完成 | BY37: 2026-01-01 12:14 | BZ37: 已完成 | CA37: 2026-01-15 18:01
A38: 王瑞 | B38: 2022210392 | C38: 计算机与信息工程学院（大学计算机教学部） | D38: 计算机科学与技术 | E38: 计科222 | F38: 已完成 | G38: 2025-09-08 10:42 | H38: 已完成 | I38: 2025-09-08 10:42 | J38: 已完成 | K38: 2025-09-08 10:42 | L38: 已完成 | M38: 2025-09-10 10:55 | N38: 已完成 | O38: 2025-09-10 10:56 | P38: 已完成 | Q38: 2025-09-10 10:56 | R38: 已完成 | S38: 2025-09-11 08:30 | T38: 已完成 | U38: 2025-09-11 08:30 | V38: 已完成 | W38: 2025-09-18 09:19 | X38: 已完成 | Y38: 2025-09-18 09:21 | Z38: 已完成 | AA38: 2025-09-20 07:55 | AB38: 已完成 | AC38: 2025-09-20 08:04 | AD38: 已完成 | AE38: 2025-09-20 08:03 | AF38: 已完成 | AG38: 2025-09-20 08:04 | AH38: 已完成 | AI38: 2025-09-20 08:12 | AJ38: 已完成 | AK38: 2025-09-20 08:28 | AL38: 已完成 | AM38: 2025-09-20 08:24 | AN38: 已完成 | AO38: 2025-09-20 08:28 | AP38: 已完成 | AQ38: 2025-09-20 08:33 | AR38: 已完成 | AS38: 2025-09-24 09:58 | AT38: 已完成 | AU38: 2025-09-24 09:58 | AV38: 已完成 | AW38: 2025-09-24 09:58 | AX38: 已完成 | AY38: 2025-09-24 10:04 | AZ38: 已完成 | BA38: 2025-09-24 11:33 | BB38: 已完成 | BC38: 2025-09-24 11:32 | BD38: 已完成 | BE38: 2025-09-24 11:33 | BF38: 已完成 | BG38: 2025-10-16 08:16 | BH38: 已完成 | BI38: 2025-09-28 09:58 | BJ38: 已完成 | BK38: 2025-09-28 09:58 | BL38: 已完成 | BM38: 2025-09-28 09:58 | BN38: 已完成 | BO38: 2025-09-28 10:08 | BP38: 已完成 | BQ38: 2025-09-28 10:14 | BR38: 已完成 | BS38: 2025-09-28 10:13 | BT38: 已完成 | BU38: 2025-09-28 10:14 | BV38: 已完成 | BW38: 2025-09-28 10:19 | BX38: 已完成 | BY38: 2025-12-31 20:19 | BZ38: 已完成 | CA38: 2026-01-15 17:58
A39: 王鑫玥 | B39: 2022210393 | C39: 计算机与信息工程学院（大学计算机教学部） | D39: 计算机科学与技术 | E39: 计科222 | F39: 已完成 | G39: 2025-09-04 08:37 | H39: 已完成 | I39: 2025-09-04 08:38 | J39: 已完成 | K39: 2025-09-04 08:38 | L39: 已完成 | M39: 2025-09-10 10:38 | N39: 已完成 | O39: 2025-09-04 08:38 | P39: 已完成 | Q39: 2025-09-04 08:43 | R39: 已完成 | S39: 2025-09-10 10:43 | T39: 已完成 | U39: 2025-09-04 08:43 | V39: 已完成 | W39: 2025-09-12 19:22 | X39: 已完成 | Y39: 2025-09-04 08:43 | Z39: 已完成 | AA39: 2025-09-15 10:11 | AB39: 已完成 | AC39: 2025-09-04 08:43 | AD39: 已完成 | AE39: 2025-09-15 10:14 | AF39: 已完成 | AG39: 2025-09-04 08:43 | AH39: 已完成 | AI39: 2025-09-15 10:19 | AJ39: 已完成 | AK39: 2025-09-04 08:43 | AL39: 已完成 | AM39: 2025-09-15 10:39 | AN39: 已完成 | AO39: 2025-09-04 08:43 | AP39: 已完成 | AQ39: 2025-09-15 10:55 | AR39: 已完成 | AS39: 2025-09-04 08:44 | AT39: 已完成 | AU39: 2025-09-17 08:07 | AV39: 已完成 | AW39: 2025-09-04 08:44 | AX39: 已完成 | AY39: 2025-09-17 08:13 | AZ39: 已完成 | BA39: 2025-09-04 08:44 | BB39: 已完成 | BC39: 2025-11-23 10:06 | BD39: 已完成 | BE39: 2025-09-04 08:44 | BF39: 已完成 | BG39: 2025-11-23 10:34 | BH39: 已完成 | BI39: 2025-09-04 08:44 | BJ39: 已完成 | BK39: 2025-11-23 13:48 | BL39: 已完成 | BM39: 2025-09-04 08:44 | BN39: 已完成 | BO39: 2025-11-23 13:50 | BP39: 已完成 | BQ39: 2025-09-04 08:44 | BR39: 已完成 | BS39: 2025-11-23 14:21 | BT39: 已完成 | BU39: 2025-11-23 14:39 | BV39: 已完成 | BW39: 2025-11-23 14:41 | BX39: 已完成 | BY39: 2026-01-09 19:20 | BZ39: 已完成 | CA39: 2026-01-15 19:53
A40: 王志成 | B40: 2022210394 | C40: 计算机与信息工程学院（大学计算机教学部） | D40: 计算机科学与技术 | E40: 计科222 | F40: 已完成 | G40: 2025-09-04 08:00 | H40: 已完成 | I40: 2025-09-04 08:00 | J40: 已完成 | K40: 2025-09-10 10:19 | L40: 已完成 | M40: 2025-09-10 10:25 | N40: 已完成 | O40: 2025-09-10 10:26 | P40: 已完成 | Q40: 2025-09-10 10:32 | R40: 已完成 | S40: 2025-09-10 10:31 | T40: 已完成 | U40: 2025-09-10 10:32 | V40: 已完成 | W40: 2025-09-11 08:53 | X40: 已完成 | Y40: 2025-09-11 08:58 | Z40: 已完成 | AA40: 2025-09-11 09:03 | AB40: 已完成 | AC40: 2025-09-18 08:09 | AD40: 已完成 | AE40: 2025-09-18 08:11 | AF40: 已完成 | AG40: 2025-09-18 08:14 | AH40: 已完成 | AI40: 2025-09-22 10:38 | AJ40: 已完成 | AK40: 2025-09-22 10:39 | AL40: 已完成 | AM40: 2025-09-22 10:42 | AN40: 已完成 | AO40: 2025-09-22 10:49 | AP40: 已完成 | AQ40: 2025-09-22 10:51 | AR40: 已完成 | AS40: 2025-09-22 10:57 | AT40: 已完成 | AU40: 2025-09-22 11:21 | AV40: 已完成 | AW40: 2025-09-28 10:14 | AX40: 已完成 | AY40: 2025-09-28 10:17 | AZ40: 已完成 | BA40: 2025-09-28 10:35 | BB40: 已完成 | BC40: 2025-10-09 08:02 | BD40: 已完成 | BE40: 2025-10-09 08:03 | BF40: 已完成 | BG40: 2025-10-16 08:26 | BH40: 已完成 | BI40: 2025-10-09 08:07 | BJ40: 已完成 | BK40: 2025-10-09 08:09 | BL40: 已完成 | BM40: 2025-10-09 08:09 | BN40: 已完成 | BO40: 2025-10-09 08:12 | BP40: 已完成 | BQ40: 2025-10-09 08:12 | BR40: 已完成 | BS40: 2025-10-09 08:14 | BT40: 已完成 | BU40: 2025-10-09 08:15 | BV40: 已完成 | BW40: 2025-10-09 08:17 | BX40: 已完成 | BY40: 2025-12-31 19:51 | BZ40: 已完成 | CA40: 2026-01-15 17:45
A41: 闫鹏飞 | B41: 2022210400 | C41: 计算机与信息工程学院（大学计算机教学部） | D41: 计算机科学与技术 | E41: 计科222 | F41: 已完成 | G41: 2025-09-04 08:08 | H41: 已完成 | I41: 2025-09-04 08:09 | J41: 已完成 | K41: 2025-09-04 08:18 | L41: 已完成 | M41: 2025-09-05 00:18 | N41: 已完成 | O41: 2025-09-05 00:18 | P41: 已完成 | Q41: 2025-09-05 00:20 | R41: 已完成 | S41: 2025-09-10 10:09 | T41: 已完成 | U41: 2025-09-10 10:13 | V41: 已完成 | W41: 2025-09-10 10:19 | X41: 已完成 | Y41: 2025-09-13 15:04 | Z41: 已完成 | AA41: 2025-09-27 18:10 | AB41: 已完成 | AC41: 2025-09-27 18:13 | AD41: 已完成 | AE41: 2025-09-27 18:17 | AF41: 已完成 | AG41: 2025-09-27 19:30 | AH41: 已完成 | AI41: 2025-09-27 19:36 | AJ41: 已完成 | AK41: 2025-09-27 19:39 | AL41: 已完成 | AM41: 2025-09-27 19:45 | AN41: 已完成 | AO41: 2025-09-27 19:46 | AP41: 已完成 | AQ41: 2025-09-27 19:50 | AR41: 已完成 | AS41: 2025-09-27 20:10 | AT41: 已完成 | AU41: 2025-09-27 20:16 | AV41: 已完成 | AW41: 2025-09-27 20:16 | AX41: 已完成 | AY41: 2025-09-27 20:21 | AZ41: 已完成 | BA41: 2025-09-27 22:55 | BB41: 已完成 | BC41: 2025-09-27 23:01 | BD41: 已完成 | BE41: 2025-09-27 23:13 | BF41: 已完成 | BG41: 2025-11-10 18:22 | BH41: 已完成 | BI41: 2025-09-28 10:27 | BJ41: 已完成 | BK41: 2025-09-28 10:31 | BL41: 已完成 | BM41: 2025-09-28 10:32 | BN41: 已完成 | BO41: 2025-09-28 10:36 | BP41: 已完成 | BQ41: 2025-09-28 10:38 | BR41: 已完成 | BS41: 2025-09-28 10:42 | BT41: 已完成 | BU41: 2025-09-28 10:49 | BV41: 已完成 | BW41: 2025-09-28 10:54 | BX41: 已完成 | BY41: 2026-01-09 19:17 | BZ41: 已完成 | CA41: 2026-01-15 17:50
A42: 杨浩天 | B42: 2022210401 | C42: 计算机与信息工程学院（大学计算机教学部） | D42: 计算机科学与技术 | E42: 计科222 | F42: 已完成 | G42: 2025-09-07 23:45 | H42: 已完成 | I42: 2025-09-07 23:45 | J42: 已完成 | K42: 2025-09-07 23:45 | L42: 已完成 | M42: 2025-09-10 10:50 | N42: 已完成 | O42: 2025-09-10 10:51 | P42: 已完成 | Q42: 2025-09-04 08:09 | R42: 已完成 | S42: 2025-09-10 10:59 | T42: 已完成 | U42: 2025-09-11 07:50 | V42: 已完成 | W42: 2025-09-11 07:55 | X42: 已完成 | Y42: 2025-09-11 08:04 | Z42: 已完成 | AA42: 2025-09-18 08:03 | AB42: 已完成 | AC42: 2025-09-24 11:31 | AD42: 已完成 | AE42: 2025-09-24 11:29 | AF42: 已完成 | AG42: 2025-09-24 11:32 | AH42: 已完成 | AI42: 2025-09-24 11:39 | AJ42: 已完成 | AK42: 2025-09-27 17:39 | AL42: 已完成 | AM42: 2025-09-27 17:45 | AN42: 已完成 | AO42: 2025-09-27 17:49 | AP42: 已完成 | AQ42: 2025-09-27 17:54 | AR42: 已完成 | AS42: 2025-09-28 10:29 | AT42: 已完成 | AU42: 2025-09-28 10:35 | AV42: 已完成 | AW42: 2025-10-09 08:42 | AX42: 已完成 | AY42: 2025-10-22 10:14 | AZ42: 已完成 | BA42: 2025-10-22 10:28 | BB42: 已完成 | BC42: 2025-10-22 10:37 | BD42: 已完成 | BE42: 2025-10-22 10:48 | BF42: 已完成 | BG42: 2025-11-11 13:07 | BH42: 已完成 | BI42: 2025-11-11 13:08 | BJ42: 已完成 | BK42: 2025-11-11 13:11 | BL42: 已完成 | BM42: 2025-11-11 13:16 | BN42: 已完成 | BO42: 2025-11-11 13:20 | BP42: 已完成 | BQ42: 2025-11-11 13:21 | BR42: 已完成 | BS42: 2025-11-11 13:25 | BT42: 已完成 | BU42: 2025-11-11 13:26 | BV42: 已完成 | BW42: 2025-11-11 13:30 | BX42: 已完成 | BY42: 2026-01-09 19:20 | BZ42: 未完成
A43: 杨龙 | B43: 2022210402 | C43: 计算机与信息工程学院（大学计算机教学部） | D43: 计算机科学与技术 | E43: 计科222 | F43: 已完成 | G43: 2025-09-11 07:52 | H43: 已完成 | I43: 2025-09-11 07:52 | J43: 已完成 | K43: 2025-09-11 07:52 | L43: 已完成 | M43: 2025-09-14 15:59 | N43: 已完成 | O43: 2025-09-04 08:25 | P43: 已完成 | Q43: 2025-09-14 16:00 | R43: 已完成 | S43: 2025-09-14 16:07 | T43: 已完成 | U43: 2025-09-14 16:14 | V43: 已完成 | W43: 2025-09-14 16:20 | X43: 已完成 | Y43: 2025-09-14 16:27 | Z43: 已完成 | AA43: 2025-09-14 16:39 | AB43: 已完成 | AC43: 2025-09-14 16:52 | AD43: 已完成 | AE43: 2025-09-14 17:19 | AF43: 已完成 | AG43: 2025-09-14 17:59 | AH43: 已完成 | AI43: 2025-09-15 10:16 | AJ43: 已完成 | AK43: 2025-10-18 12:32 | AL43: 已完成 | AM43: 2025-10-18 12:38 | AN43: 已完成 | AO43: 2025-10-18 13:12 | AP43: 已完成 | AQ43: 2025-10-18 13:33 | AR43: 已完成 | AS43: 2025-10-18 14:17 | AT43: 已完成 | AU43: 2025-11-11 13:01 | AV43: 已完成 | AW43: 2025-11-11 14:07 | AX43: 已完成 | AY43: 2025-11-11 14:12 | AZ43: 已完成 | BA43: 2025-11-21 21:44 | BB43: 已完成 | BC43: 2025-11-21 21:51 | BD43: 已完成 | BE43: 2025-11-21 21:52 | BF43: 已完成 | BG43: 2025-11-21 21:56 | BH43: 已完成 | BI43: 2025-11-21 21:58 | BJ43: 已完成 | BK43: 2025-11-21 22:02 | BL43: 已完成 | BM43: 2025-11-21 22:05 | BN43: 已完成 | BO43: 2025-11-21 22:08 | BP43: 已完成 | BQ43: 2025-11-21 22:10 | BR43: 已完成 | BS43: 2025-11-21 22:14 | BT43: 已完成 | BU43: 2025-11-21 22:15 | BV43: 已完成 | BW43: 2025-11-21 22:19 | BX43: 已完成 | BY43: 2026-01-09 19:30 | BZ43: 已完成 | CA43: 2026-01-15 19:34
A44: 詹庆 | B44: 2022210404 | C44: 计算机与信息工程学院（大学计算机教学部） | D44: 计算机科学与技术 | E44: 计科222 | F44: 已完成 | G44: 2025-09-10 10:02 | H44: 已完成 | I44: 2025-09-10 10:02 | J44: 已完成 | K44: 2025-09-10 10:03 | L44: 已完成 | M44: 2025-09-11 07:45 | N44: 已完成 | O44: 2025-09-11 07:46 | P44: 已完成 | Q44: 2025-09-11 07:47 | R44: 已完成 | S44: 2025-09-11 07:50 | T44: 已完成 | U44: 2025-09-11 08:24 | V44: 已完成 | W44: 2025-09-11 08:27 | X44: 已完成 | Y44: 2025-09-11 08:29 | Z44: 已完成 | AA44: 2025-09-18 07:59 | AB44: 已完成 | AC44: 2025-09-18 07:59 | AD44: 已完成 | AE44: 2025-09-18 08:02 | AF44: 已完成 | AG44: 2025-09-18 08:03 | AH44: 已完成 | AI44: 2025-09-18 08:09 | AJ44: 已完成 | AK44: 2025-09-18 08:09 | AL44: 已完成 | AM44: 2025-09-18 08:12 | AN44: 已完成 | AO44: 2025-09-18 08:25 | AP44: 已完成 | AQ44: 2025-09-18 08:28 | AR44: 已完成 | AS44: 2025-09-18 08:29 | AT44: 已完成 | AU44: 2025-09-28 09:59 | AV44: 已完成 | AW44: 2025-09-28 10:00 | AX44: 已完成 | AY44: 2025-09-28 10:06 | AZ44: 已完成 | BA44: 2025-09-28 10:07 | BB44: 已完成 | BC44: 2025-09-28 10:14 | BD44: 已完成 | BE44: 2025-09-28 10:19 | BF44: 已完成 | BG44: 2025-10-17 20:03 | BH44: 已完成 | BI44: 2025-09-28 10:24 | BJ44: 已完成 | BK44: 2025-09-28 10:29 | BL44: 已完成 | BM44: 2025-09-28 10:37 | BN44: 已完成 | BO44: 2025-10-08 13:26 | BP44: 已完成 | BQ44: 2025-10-08 13:26 | BR44: 已完成 | BS44: 2025-10-08 13:30 | BT44: 已完成 | BU44: 2025-10-08 13:31 | BV44: 已完成 | BW44: 2025-10-08 13:35 | BX44: 已完成 | BY44: 2026-01-09 19:17 | BZ44: 已完成 | CA44: 2026-01-15 17:34
A45: 张金龙 | B45: 2022210405 | C45: 计算机与信息工程学院（大学计算机教学部） | D45: 计算机科学与技术 | E45: 计科222 | F45: 已完成 | G45: 2025-09-04 08:08 | H45: 已完成 | I45: 2025-09-08 10:07 | J45: 已完成 | K45: 2025-09-08 10:07 | L45: 已完成 | M45: 2025-09-08 10:14 | N45: 已完成 | O45: 2025-09-08 10:14 | P45: 已完成 | Q45: 2025-09-10 10:44 | R45: 已完成 | S45: 2025-09-27 17:36 | T45: 已完成 | U45: 2025-09-27 17:36 | V45: 已完成 | W45: 2025-09-28 09:57 | X45: 已完成 | Y45: 2025-09-28 09:57 | Z45: 已完成 | AA45: 2025-10-09 07:58 | AB45: 已完成 | AC45: 2025-10-09 07:58 | AD45: 已完成 | AE45: 2025-10-09 08:11 | AF45: 已完成 | AG45: 2025-10-09 08:12 | AH45: 已完成 | AI45: 2025-10-09 08:19 | AJ45: 已完成 | AK45: 2025-10-09 08:19 | AL45: 已完成 | AM45: 2025-10-09 08:25 | AN45: 已完成 | AO45: 2025-10-09 08:26 | AP45: 已完成 | AQ45: 2025-10-09 08:30 | AR45: 已完成 | AS45: 2025-10-23 08:12 | AT45: 已完成 | AU45: 2025-10-23 08:17 | AV45: 已完成 | AW45: 2025-10-23 08:18 | AX45: 已完成 | AY45: 2025-10-23 08:23 | AZ45: 已完成 | BA45: 2025-11-03 09:46 | BB45: 已完成 | BC45: 2025-11-03 09:52 | BD45: 已完成 | BE45: 2025-11-03 09:54 | BF45: 已完成 | BG45: 2025-11-03 09:58 | BH45: 已完成 | BI45: 2025-11-03 09:58 | BJ45: 已完成 | BK45: 2025-11-03 10:02 | BL45: 已完成 | BM45: 2025-11-03 10:03 | BN45: 已完成 | BO45: 2025-11-03 10:06 | BP45: 已完成 | BQ45: 2025-11-03 10:06 | BR45: 已完成 | BS45: 2025-11-03 10:11 | BT45: 已完成 | BU45: 2025-11-03 10:11 | BV45: 已完成 | BW45: 2025-11-03 10:16 | BX45: 已完成 | BY45: 2026-01-06 22:17 | BZ45: 已完成 | CA45: 2026-01-15 17:53
